Workbook

Sheet Table S1_MAG quality
A1: Table S1. MAG quality
A2: Empty template for MAG quality, taxonomy, assembly statistics, and relative abundance across CAN_1–CAN_5.
A3: MAG bin name | B3: MAG iteration ID | C3: 14 | D3: 1 | E3: Taxonomy | F3: 12 | G3: 13 | H3: Compl. (%) | I3: Contamin (%) | J3: Genome size | K3: Contig number | L3: GC | M3: N50 (bp) | N3: rel_abun in CAN_1 | O3: rel_abun in CAN_2 | P3: rel_abun in CAN_3 | Q3: rel_abun in CAN_4 | R3: rel_abun in CAN_5
C4: Phylum | D4: Class | E4: Order | F4: Family | G4: Genus
A5: CAN_1_bin.148 | B5: Dokdonella.13 | C5: Pseudomonadota | D5: Gammaproteobacteria | E5: Xanthomonadales | F5: Rhodanobacteraceae | G5: Dokdonella | H5: 95.69 | I5: 7.58 | J5: 4210296 | K5: 46 | L5: 0.69 | M5: 415687 | N5: 0.003611728 | O5: 0.004485683 | P5: 0.004445603 | Q5: 0.000991 | R5: 0.000191
A6: CAN_1_bin.174 | B6: UBA5532_m.1 | C6: Patescibacteria | D6: JAEDAM01 | E6: BD1-5 | F6: UBA2023 | G6: UBA5532 | H6: 97.22 | I6: 1.35 | J6: 1166702 | K6: 1 | L6: 0.43 | M6: 1166702 | N6: 0.03028026 | O6: 0.007001495 | P6: 0.010296311 | Q6: 0.005247412 | R6: 0.00345912
A7: CAN_1_bin.177 | B7: midas_g_155.3 | C7: Pseudomonadota | D7: Alphaproteobacteria | E7: Rhodobacterales | F7: Rhodobacteraceae | G7: Pararhodobacter | H7: 100 | I7: 0.15 | J7: 4385690 | K7: 2 | L7: 0.68 | M7: 3311625 | N7: 0.003267175 | O7: 0.002588946 | P7: 0.002613809 | Q7: 0.003671736 | R7: 0.001538334
A8: CAN_1_bin.180 | B8: Bdellovibrio.13 | C8: Bdellovibrionota | D8: Bdellovibrionia | E8: Bdellovibrionales | F8: Bdellovibrionaceae | G8: UBA2316 | H8: 99.98 | I8: 0.52 | J8: 4039223 | K8: 20 | L8: 0.34 | M8: 593163 | N8: 0.002546397 | O8: 0.000756 | P8: 0.001003109 | Q8: 0.000226 | R8: 3.57e-05
A9: CAN_1_bin.195 | B9: UBA919_m.1 | C9: Patescibacteria | D9: ABY1 | E9: BM507 | F9: UBA917 | G9: UBA919 | H9: 97.28 | I9: 1.45 | J9: 894103 | K9: 1 | L9: 0.4 | M9: 894103 | N9: 0.00320921 | O9: 0.000658 | P9: 0.001034346 | Q9: 0.004408273 | R9: 0.001836505
A10: CAN_1_bin.2 | B10: B-1AR_m.1 | C10: Bacteroidota | D10: Ignavibacteria | E10: SJA-28 | F10: B-1AR | H10: 98.74 | I10: 1.2 | J10: 3126569 | K10: 1 | L10: 0.35 | M10: 3126569 | N10: 0.00189427 | O10: 0.000461 | P10: 0.000817 | Q10: 0.005366112 | R10: 0.005835915
A11: CAN_1_bin.210 | B11: Dokdonella.14 | C11: Pseudomonadota | D11: Gammaproteobacteria | E11: Xanthomonadales | F11: Rhodanobacteraceae | G11: Dokdonella | H11: 99.55 | I11: 0.45 | J11: 3941745 | K11: 13 | L11: 0.69 | M11: 728973 | N11: 0.009766223 | O11: 0.013387657 | P11: 0.013225006 | Q11: 0.011006405 | R11: 0.001762958
A12: CAN_1_bin.48 | B12: GWB1-50-10_m.1 | C12: Patescibacteria | D12: Paceibacteria | E12: UBA6257 | F12: GWB1-50-10 | H12: 100 | I12: 0.1 | J12: 668260 | K12: 1 | L12: 0.44 | M12: 668260 | N12: 0.002868404 | O12: 0.00263992 | P12: 0.002592972 | Q12: 4.33e-05 | R12: 3.68e-05
A13: CAN_1_bin.5 | B13: UBA1573_m.1 | C13: Pseudomonadota | D13: Alphaproteobacteria | E13: Micavibrionales | F13: Micavibrionaceae | G13: UBA1573 | H13: 100 | I13: 2.92 | J13: 2295354 | K13: 2 | L13: 0.45 | M13: 1600197 | N13: 0.004824322 | O13: 0.003347207 | P13: 0.003304787 | Q13: 0.013089252 | R13: 0.017626096
A14: CAN_1_bin.77 | B14: UBA5066_m.1 | C14: Acidobacteriota | D14: Thermoanaerobaculia | E14: UBA5066 | F14: UBA5066 | G14: UBA5066 | H14: 97.68 | I14: 0.28 | J14: 5985155 | K14: 4 | L14: 0.7 | M14: 1686115 | N14: 0.010532733 | O14: 0.012878474 | P14: 0.012526772 | Q14: 0.019967309 | R14: 0.0495223
A15: CAN_1_bin.84 | B15: CFX2_m.1 | C15: Chloroflexota | D15: Anaerolineae | E15: Aggregatilineales | F15: Phototrophicaceae | G15: CFX2 | H15: 96.16 | I15: 2.61 | J15: 6398485 | K15: 8 | L15: 0.55 | M15: 3749479 | N15: 0.005559483 | O15: 0.004930177 | P15: 0.005031585 | Q15: 0.001603134 | R15: 0.000277
A16: CAN_1_bin.98 | B16: Ca_Accumulibacter.23 | C16: Pseudomonadota | D16: Gammaproteobacteria | E16: Burkholderiales | F16: Rhodocyclaceae | G16: Accumulibacter | H16: 100 | I16: 0.19 | J16: 5022376 | K16: 6 | L16: 0.65 | M16: 3573482 | N16: 0.033631117 | O16: 0.02515896 | P16: 0.02536908 | Q16: 0.11391873 | R16: 0.041523786
A17: CAN_2_bin.125 | B17: Pseudoxanthomonas_A_m.1 | C17: Pseudomonadota | D17: Gammaproteobacteria | E17: Xanthomonadales | F17: Xanthomonadaceae | G17: Pseudoxanthomonas_A | H17: 99.78 | I17: 1.71 | J17: 3440139 | K17: 25 | L17: 0.68 | M17: 222642 | N17: 0.02209988 | O17: 0.03671151 | P17: 0.035104854 | Q17: 0.00059 | R17: 0.000126
A18: CAN_2_bin.151 | B18: Brevundimonas.4 | C18: Pseudomonadota | D18: Alphaproteobacteria | E18: Caulobacterales | F18: Caulobacteraceae | G18: Brevundimonas | H18: 99.99 | I18: 1.73 | J18: 2857677 | K18: 2 | L18: 0.68 | M18: 2456369 | N18: 0.003811263 | O18: 0.006971384 | P18: 0.006640263 | Q18: 0.000494 | R18: 0.001051654
A19: CAN_2_bin.159 | B19: Pseudoxanthomonas.23 | C19: Pseudomonadota | D19: Gammaproteobacteria | E19: Xanthomonadales | F19: Xanthomonadaceae | G19: Pseudoxanthomonas | H19: 100 | I19: 0.02 | J19: 2816656 | K19: 3 | L19: 0.7 | M19: 1658373 | N19: 0.012928113 | O19: 0.00873372 | P19: 0.008937194 | Q19: 0.02519797 | R19: 0.007934008
A20: CAN_2_bin.173 | B20: JACDQM01_m.1 | C20: Pseudomonadota | D20: Gammaproteobacteria | E20: Burkholderiales | F20: Burkholderiaceae | G20: JACDQM01 | H20: 88.51 | I20: 3.03 | J20: 3870350 | K20: 145 | L20: 0.69 | M20: 37630 | N20: 0.000685 | O20: 0.001854193 | P20: 0.001708084 | Q20: 0.000201 | R20: 0.000158
A21: CAN_2_bin.176 | B21: UBA5066_m.2 | C21: Acidobacteriota | D21: Thermoanaerobaculia | E21: UBA5066 | F21: UBA5066 | G21: UBA5066 | H21: 95.76 | I21: 0.52 | J21: 5834731 | K21: 4 | L21: 0.7 | M21: 2059594 | N21: 0.004208347 | O21: 0.007036818 | P21: 0.006669267 | Q21: 0.000464 | R21: 0.000399
A22: CAN_2_bin.23 | B22: Zoogloea.11 | C22: Pseudomonadota | D22: Gammaproteobacteria | E22: Burkholderiales | F22: Rhodocyclaceae | G22: Zoogloea | H22: 96.04 | I22: 0.54 | J22: 4657897 | K22: 32 | L22: 0.66 | M22: 295469 | N22: 0.005985822 | O22: 0.008841831 | P22: 0.00836177 | Q22: 0.00049 | R22: 0.000638
A23: CAN_2_bin.6 | B23: Denitratisoma.2 | C23: Pseudomonadota | D23: Gammaproteobacteria | E23: Burkholderiales | F23: Rhodocyclaceae | G23: Desulfobacillus | H23: 99.7 | I23: 0.37 | J23: 3163088 | K23: 4 | L23: 0.65 | M23: 950453 | N23: 0.017174284 | O23: 0.006393228 | P23: 0.007236849 | Q23: 0.007495629 | R23: 0.000318
A24: CAN_2_bin.66 | B24: JACTMZ01_m.1 | C24: Verrucomicrobiota | D24: Verrucomicrobiae | E24: Chthoniobacterales | F24: JACTMZ01 | G24: JACTMZ01 | H24: 87.35 | I24: 1.04 | J24: 2784204 | K24: 69 | L24: 0.63 | M24: 77074 | N24: 0.000982 | O24: 0.001388278 | P24: 0.001405915 | Q24: 0.000492 | R24: 0.000224
... A52: CAN_4_bin.35 | B52: Brevundimonas.7 | C52: Pseudomonadota | D52: Alphaproteobacteria | E52: Caulobacterales | F52: Caulobacteraceae | G52: Brevundimonas | H52: 100 | I52: 0.06 | J52: 2759345 | K52: 3 | L52: 0.66 | M52: 2730425 | N52: 0.000416 | O52: 0.00021 | P52: 0.000243 | Q52: 0.004082246 | R52: 0.000286
A53: CAN_4_bin.38 | B53: Salinispiraceae_m.1 | C53: Spirochaetota | D53: Spirochaetia | E53: DSM-27196 | F53: Salinispiraceae | H53: 65.19 | I53: 0.7 | J53: 2595407 | K53: 45 | L53: 0.53 | M53: 79947 | N53: 0.00017 | O53: 0.000168 | P53: 0.000172 | Q53: 0.00118189 | R53: 4.51e-05
A54: CAN_4_bin.44 | B54: Mesorhizobium.22 | C54: Pseudomonadota | D54: Alphaproteobacteria | E54: Rhizobiales | F54: Rhizobiaceae | G54: DUSC01 | H54: 99.99 | I54: 0.07 | J54: 5523224 | K54: 5 | L54: 0.67 | M54: 1873950 | N54: 0.000536 | O54: 0.00048 | P54: 0.000503 | Q54: 0.001886164 | R54: 0.002068712
A55: CAN_4_bin.62 | B55: JARKPB01_m.1 | C55: Chloroflexota | D55: Anaerolineae | E55: Anaerolineales | F55: Anaerolineaceae | G55: JARKPB01 | H55: 55.96 | I55: 2.44 | J55: 1992954 | K55: 83 | L55: 0.6 | M55: 31753 | N55: 0.000158 | O55: 0.000132 | P55: 0.000139 | Q55: 0.001276129 | R55: 0.000329
A56: CAN_4_bin.64 | B56: Accumulibacter_m.2 | C56: Pseudomonadota | D56: Gammaproteobacteria | E56: Burkholderiales | F56: Rhodocyclaceae | G56: Accumulibacter | H56: 79.98 | I56: 1.84 | J56: 3842927 | K56: 53 | L56: 0.64 | M56: 109616 | N56: 0.005256289 | O56: 0.002262134 | P56: 0.002572883 | Q56: 0.009598464 | R56: 0.003685772
A57: CAN_4_bin.70 | B57: JAIOHN01_m.1 | C57: Chloroflexota | D57: Anaerolineae | E57: Aggregatilineales | F57: Phototrophicaceae | G57: JAIOHN01 | H57: 73.66 | I57: 1.16 | J57: 4082294 | K57: 54 | L57: 0.62 | M57: 132652 | N57: 0.000228 | O57: 0.000145 | P57: 0.000158 | Q57: 0.00108192 | R57: 0.0005
A58: CAN_4_bin.72 | B58: Competibacter_A_m.1 | C58: Pseudomonadota | D58: Gammaproteobacteria | E58: Competibacterales | F58: Competibacteraceae | G58: Competibacter_A | H58: 61.54 | I58: 5.05 | J58: 3004766 | K58: 112 | L58: 0.59 | M58: 39667 | N58: 0.010135044 | O58: 0.010248994 | P58: 0.010369587 | Q58: 0.004742864 | R58: 0.002621284
A59: CAN_4_bin.76 | B59: Brojett037_m.1 | C59: Patescibacteria | D59: Dojkabacteria | E59: J137 | F59: J137 | G59: Brojett037 | H59: 53.34 | I59: 0.39 | J59: 623697 | K59: 23 | L59: 0.33 | M59: 33654 | N59: 7.04e-05 | O59: 3.83e-05 | P59: 4.6e-05 | Q59: 0.000267 | R59: 1.27e-05
A60: CAN_4_bin.92 | B60: Flexifilum_m.1 | C60: Chloroflexota | D60: Anaerolineae | E60: Aggregatilineales | F60: Phototrophicaceae | G60: Flexifilum | H60: 84.51 | I60: 6.83 | J60: 3994020 | K60: 91 | L60: 0.63 | M60: 86287 | N60: 0.000314 | O60: 0.000262 | P60: 0.000267 | Q60: 0.000933 | R60: 0.001900647
A61: CAN_5_bin.1 | B61: Rhabdaerophilum_m.1 | C61: Pseudomonadota | D61: Alphaproteobacteria | E61: Rhizobiales | F61: Beijerinckiaceae | G61: Rhabdaerophilum | H61: 100 | I61: 0.04 | J61: 3153730 | K61: 1 | L61: 0.64 | M61: 3153730 | N61: 0.000541 | O61: 0.00044 | P61: 0.000463 | Q61: 0.000902 | R61: 0.003058194
A62: CAN_5_bin.100 | B62: JAEXTR01_m.1 | C62: Bacteroidota | D62: Ignavibacteria | E62: Ignavibacteriales | F62: Ignavibacteriaceae | G62: JAEXTR01 | H62: 81.06 | I62: 0.18 | J62: 3252921 | K62: 5 | L62: 0.44 | M62: 840523 | N62: 0.001031642 | O62: 0.00087 | P62: 0.00093 | Q62: 0.001476168 | R62: 0.003898476
A63: CAN_5_bin.106 | B63: Ca_Competibacter.139 | C63: Pseudomonadota | D63: Gammaproteobacteria | E63: Competibacterales | F63: Competibacteraceae | G63: Competibacter | H63: 92.13 | I63: 4.17 | J63: 2984512 | K63: 51 | L63: 0.62 | M63: 105487 | N63: 0.26809792 | O63: 0.26609695 | P63: 0.27174007 | Q63: 0.11192626 | R63: 0.065415
A64: CAN_5_bin.112 | B64: Terrimonas.22 | C64: Bacteroidota | D64: Bacteroidia | E64: Chitinophagales | F64: Chitinophagaceae | G64: JJ008 | H64: 100 | I64: 0.05 | J64: 4028776 | K64: 1 | L64: 0.42 | M64: 4028776 | N64: 0.000297 | O64: 0.000115 | P64: 0.000152 | Q64: 0.007590076 | R64: 0.027768152
A65: CAN_5_bin.145 | B65: JAAFHL01_m.1 | C65: Bacteroidota | D65: Bacteroidia | E65: J057 | F65: J057 | G65: JAAFHL01 | H65: 98.65 | I65: 0.1 | J65: 4785324 | K65: 1 | L65: 0.49 | M65: 4785324 | N65: 0.000541 | O65: 0.000451 | P65: 0.000455 | Q65: 4.5e-05 | R65: 0.003470299
... A70: CAN_5_bin.167 | B70: OLB5_m.2 | C70: Bacteroidota | D70: Ignavibacteria | E70: SJA-28 | F70: OLB5 | G70: OLB5 | H70: 63.96 | I70: 2.89 | J70: 3179265 | K70: 66 | L70: 0.42 | M70: 76706 | N70: 2.79e-05 | O70: 2.91e-05 | P70: 3.1e-05 | Q70: 7.57e-05 | R70: 0.000924
A71: CAN_5_bin.169 | B71: GWE2-31-10_m.1 | C71: Spirochaetota | D71: GWE2-31-10 | E71: GWE2-31-10 | F71: GWE2-31-10 | H71: 56.96 | I71: 0.67 | J71: 3117418 | K71: 17 | L71: 0.43 | M71: 295341 | N71: 3.23e-05 | O71: 3.84e-05 | P71: 4.13e-05 | Q71: 0.000225 | R71: 0.001146911
...

Sheet Table S2a_RPKM per MAG
A1: Table S2a. Abundance of target genes (RPKM) per MAG
A2: K00376 is split into nosZ I and nosZ II columns.
A3: MAGs | B3: iterative ID | C3: RPKM_K00023 | D3: RPKM_K00362 | E3: RPKM_K00363 | F3: RPKM_K00368 | G3: RPKM_K00370 | H3: RPKM_K00371 | I3: RPKM_K00374 | J3: RPKM_nosZ I | K3: RPKM_nosZ II | L3: RPKM_K00626 | M3: RPKM_K00634 | N3: RPKM_K00688 | O3: RPKM_K00700 | P3: RPKM_K00702 | Q3: RPKM_K00703 | R3: RPKM_K00925 | S3: RPKM_K00937 | T3: RPKM_K01214 | U3: RPKM_K01514 | V3: RPKM_K01659 | W3: RPKM_K01720 | X3: RPKM_K01847 | Y3: RPKM_K01848 | Z3: RPKM_K01895 | AA3: RPKM_K01908 | AB3: RPKM_K02035 | AC3: RPKM_K02036 | AD3: RPKM_K02037 | AE3: RPKM_K02038 | AF3: RPKM_K02039 | AG3: RPKM_K02040 | AH3: RPKM_K02305 | AI3: RPKM_K02567 | AJ3: RPKM_K02568 | AK3: RPKM_K03385 | AL3: RPKM_K03821 | AM3: RPKM_K04561 | AN3: RPKM_K05973 | AO3: RPKM_K07636 | AP3: RPKM_K07657 | AQ3: RPKM_K15864 | AR3: RPKM_K15876 | AS3: RPKM_K22468
A4: CAN_1_bin.148 | B4: Dokdonella.13 | C4: 0 | D4: 0 | E4: 0 | F4: 0 | G4: 0 | H4: 0 | I4: 0 | J4: 0 | K4: 0 | L4: 1.6666 | M4: 0 | N4: 0 | O4: 0 | P4: 0 | Q4: 0 | R4: 0 | S4: 0.6807 | T4: 0 | U4: 0 | V4: 0 | W4: 0 | X4: 0 | Y4: 0 | Z4: 0 | AA4: 0 | AB4: 0 | AC4: 2.5897 | AD4: 2.2641 | AE4: 2.2716 | AF4: 2.7227 | AG4: 2.0231 | AH4: 0 | AI4: 0 | AJ4: 0 | AK4: 0 | AL4: 0 | AM4: 0 | AN4: 0 | AO4: 2.8524 | AP4: 2.7796 | AQ4: 0 | AR4: 0 | AS4: 0
A5: CAN_1_bin.174 | B5: UBA5532_m.1 | C5: 0 | D5: 0 | E5: 0 | F5: 0 | G5: 0 | H5: 0 | I5: 0 | J5: 0 | K5: 0 | L5: 0 | M5: 0 | N5: 0 | O5: 0 | P5: 0 | Q5: 0 | R5: 0 | S5: 0 | T5: 0 | U5: 0 | V5: 0 | W5: 0 | X5: 0 | Y5: 0 | Z5: 0 | AA5: 0 | AB5: 0 | AC5: 0 | AD5: 0 | AE5: 0 | AF5: 0 | AG5: 0 | AH5: 0 | AI5: 0 | AJ5: 0 | AK5: 0 | AL5: 0 | AM5: 0 | AN5: 0 | AO5: 0 | AP5: 0 | AQ5: 0 | AR5: 0 | AS5: 0
A6: CAN_1_bin.177 | B6: midas_g_155.3 | C6: 0 | D6: 0 | E6: 0 | F6: 0 | G6: 0 | H6: 0 | I6: 0 | J6: 0 | K6: 0 | L6: 0 | M6: 0 | N6: 0 | O6: 0 | P6: 0 | Q6: 0 | R6: 0 | S6: 0 | T6: 0 | U6: 0 | V6: 0 | W6: 0 | X6: 0 | Y6: 0 | Z6: 0 | AA6: 0 | AB6: 0 | AC6: 0 | AD6: 0 | AE6: 0 | AF6: 0 | AG6: 0 | AH6: 0 | AI6: 0 | AJ6: 0 | AK6: 0 | AL6: 0 | AM6: 0 | AN6: 0 | AO6: 0 | AP6: 0 | AQ6: 0 | AR6: 0 | AS6: 0
A7: CAN_1_bin.180 | B7: Bdellovibrio.13 | C7: 0 | D7: 0 | E7: 0 | F7: 0 | G7: 0 | H7: 0 | I7: 0 | J7: 0 | K7: 0 | L7: 0 | M7: 0 | N7: 0 | O7: 0 | P7: 0 | Q7: 0 | R7: 0 | S7: 0 | T7: 0 | U7: 0 | V7: 0 | W7: 0 | X7: 0 | Y7: 0 | Z7: 0 | AA7: 0 | AB7: 0 | AC7: 0 | AD7: 0 | AE7: 0 | AF7: 0 | AG7: 0 | AH7: 0 | AI7: 0 | AJ7: 0 | AK7: 0 | AL7: 0 | AM7: 0 | AN7: 0 | AO7: 0 | AP7: 0 | AQ7: 0 | AR7: 0 | AS7: 0
A8: CAN_1_bin.195 | B8: UBA919_m.1 | C8: 0 | D8: 0 | E8: 0 | F8: 0 | G8: 0 | H8: 0 | I8: 0 | J8: 0 | K8: 0 | L8: 0 | M8: 0 | N8: 0 | O8: 0 | P8: 0 | Q8: 0 | R8: 0 | S8: 0 | T8: 0 | U8: 0 | V8: 0 | W8: 0 | X8: 0 | Y8: 0 | Z8: 0 | AA8: 0 | AB8: 0 | AC8: 0 | AD8: 0 | AE8: 0 | AF8: 0 | AG8: 0 | AH8: 0 | AI8: 0 | AJ8: 0 | AK8: 0 | AL8: 0 | AM8: 0 | AN8: 0 | AO8: 0 | AP8: 0 | AQ8: 0 | AR8: 0 | AS8: 0
A9: CAN_1_bin.2 | B9: B-1AR_m.1 | C9: 0 | D9: 0 | E9: 0 | F9: 0 | G9: 0 | H9: 0 | I9: 0 | J9: 0 | K9: 0 | L9: 0 | M9: 0 | N9: 0 | O9: 0 | P9: 0 | Q9: 0 | R9: 0 | S9: 0 | T9: 0 | U9: 0 | V9: 0 | W9: 0 | X9: 0 | Y9: 0 | Z9: 0 | AA9: 0 | AB9: 0 | AC9: 0 | AD9: 0 | AE9: 0 | AF9: 0 | AG9: 0 | AH9: 0 | AI9: 0 | AJ9: 0 | AK9: 0 | AL9: 0 | AM9: 0 | AN9: 0 | AO9: 0 | AP9: 0 | AQ9: 0 | AR9: 0 | AS9: 0
A10: CAN_1_bin.210 | B10: Dokdonella.14 | C10: 0 | D10: 0 | E10: 0 | F10: 0 | G10: 0 | H10: 0 | I10: 0 | J10: 0 | K10: 0 | L10: 0 | M10: 0 | N10: 0 | O10: 0 | P10: 0 | Q10: 0 | R10: 0 | S10: 0 | T10: 0 | U10: 0 | V10: 0 | W10: 0 | X10: 0 | Y10: 0 | Z10: 0 | AA10: 0 | AB10: 0 | AC10: 0 | AD10: 0 | AE10: 0 | AF10: 0 | AG10: 0 | AH10: 0 | AI10: 0 | AJ10: 0 | AK10: 0 | AL10: 0 | AM10: 0 | AN10: 0 | AO10: 0 | AP10: 0 | AQ10: 0 | AR10: 0 | AS10: 0
A11: CAN_1_bin.48 | B11: GWB1-50-10_m.1 | C11: 0 | D11: 0 | E11: 0 | F11: 0 | G11: 0 | H11: 0 | I11: 0 | J11: 0 | K11: 0 | L11: 0 | M11: 0 | N11: 0 | O11: 0 | P11: 0 | Q11: 0 | R11: 0 | S11: 0 | T11: 0 | U11: 0 | V11: 0 | W11: 0 | X11: 0 | Y11: 0 | Z11: 0 | AA11: 0 | AB11: 0 | AC11: 0 | AD11: 0 | AE11: 0 | AF11: 0 | AG11: 0 | AH11: 0 | AI11: 0 | AJ11: 0 | AK11: 0 | AL11: 0 | AM11: 0 | AN11: 0 | AO11: 0 | AP11: 0 | AQ11: 0 | AR11: 0 | AS11: 0
A12: CAN_1_bin.5 | B12: UBA1573_m.1 | C12: 20.0615 | D12: 0 | E12: 0 | F12: 0 | G12: 0 | H12: 0 | I12: 0 | J12: 0 | K12: 0 | L12: 0 | M12: 0 | N12: 0 | O12: 0 | P12: 0 | Q12: 0 | R12: 19.8714 | S12: 0 | T12: 0 | U12: 0 | V12: 0 | W12: 0 | X12: 0 | Y12: 0 | Z12: 0 | AA12: 0 | AB12: 0 | AC12: 0 | AD12: 0 | AE12: 0 | AF12: 0 | AG12: 0 | AH12: 0 | AI12: 0 | AJ12: 0 | AK12: 0 | AL12: 10.9995 | AM12: 0 | AN12: 0 | AO12: 0 | AP12: 0 | AQ12: 0 | AR12: 0 | AS12: 0
A13: CAN_1_bin.77 | B13: UBA5066_m.1 | C13: 0 | D13: 0 | E13: 0 | F13: 0 | G13: 0 | H13: 0 | I13: 0 | J13: 0 | K13: 0 | L13: 0 | M13: 0 | N13: 0 | O13: 0 | P13: 0 | Q13: 0 | R13: 0 | S13: 0 | T13: 0 | U13: 0 | V13: 0 | W13: 0 | X13: 0 | Y13: 13.2034 | Z13: 0 | AA13: 0 | AB13: 0 | AC13: 0 | AD13: 0 | AE13: 0 | AF13: 0 | AG13: 0 | AH13: 0 | AI13: 0 | AJ13: 0 | AK13: 0 | AL13: 0 | AM13: 0 | AN13: 0 | AO13: 0 | AP13: 0 | AQ13: 0 | AR13: 0 | AS13: 0
A14: CAN_1_bin.84 | B14: CFX2_m.1 | C14: 0 | D14: 0 | E14: 0 | F14: 3.9772 | G14: 0 | H14: 0 | I14: 0 | J14: 0 | K14: 0 | L14: 14.4015 | M14: 0 | N14: 0 | O14: 0 | P14: 0 | Q14: 0 | R14: 0 | S14: 0 | T14: 0 | U14: 0 | V14: 0 | W14: 0 | X14: 0 | Y14: 0 | Z14: 0 | AA14: 0 | AB14: 0 | AC14: 3.0828 | AD14: 8.6744 | AE14: 2.4459 | AF14: 0 | AG14: 0 | AH14: 0 | AI14: 0 | AJ14: 0 | AK14: 0 | AL14: 0 | AM14: 0 | AN14: 0 | AO14: 0 | AP14: 0 | AQ14: 0 | AR14: 0 | AS14: 0
A15: CAN_1_bin.98 | B15: Ca_Accumulibacter.23 | C15: 0 | D15: 48.1471 | E15: 31.4653 | F15: 0 | G15: 0 | H15: 0 | I15: 0 | J15: 0 | K15: 0 | L15: 101.243 | M15: 0 | N15: 44.9363 | O15: 0 | P15: 0 | Q15: 39.8832 | R15: 0 | S15: 0 | T15: 0 | U15: 0 | V15: 0 | W15: 0 | X15: 0 | Y15: 0 | Z15: 0 | AA15: 0 | AB15: 0 | AC15: 0 | AD15: 0 | AE15: 0 | AF15: 0 | AG15: 45.5818 | AH15: 0 | AI15: 0 | AJ15: 0 | AK15: 0 | AL15: 80.1853 | AM15: 0 | AN15: 0 | AO15: 0 | AP15: 0 | AQ15: 0 | AR15: 0 | AS15: 38.7903
... A279: coasm_bin.93 | B279: midas_g_4351.1 | C279: 0.7462 | D279: 0 | E279: 0 | F279: 0 | G279: 0 | H279: 0 | I279: 0 | J279: 0 | K279: 0 | L279: 6.2376 | M279: 0 | N279: 0 | O279: 0 | P279: 0 | Q279: 0 | R279: 0 | S279: 0.5671 | T279: 0 | U279: 0 | V279: 0 | W279: 0 | X279: 2.1145 | Y279: 0 | Z279: 0.4933 | AA279: 0 | AB279: 3.2753 | AC279: 0.9433 | AD279: 0.3381 | AE279: 0.7515 | AF279: 0.9997 | AG279: 0.609 | AH279: 0 | AI279: 0 | AJ279: 0 | AK279: 0 | AL279: 2.3185 | AM279: 0 | AN279: 0.7925 | AO279: 0.7073 | AP279: 1.0472 | AQ279: 0 | AR279: 0 | AS279: 0.3629

Sheet Table S2b_RPKM per sample
A1: Table S2b. Abundance of target genes (RPKM) per sample
A2: Use one row per sample. K00376 is split into nosZ I and nosZ II columns.
A3: Sample ID | B3: RPKM_K00023 | C3: RPKM_K00362 | D3: RPKM_K00363 | E3: RPKM_K00368 | F3: RPKM_K00370 | G3: RPKM_K00371 | H3: RPKM_K00374 | I3: RPKM_nosZ I | J3: RPKM_nosZ II | K3: RPKM_K00626 | L3: RPKM_K00634 | M3: RPKM_K00688 | N3: RPKM_K00700 | O3: RPKM_K00702 | P3: RPKM_K00703 | Q3: RPKM_K00925 | R3: RPKM_K00937 | S3: RPKM_K01214 | T3: RPKM_K01514 | U3: RPKM_K01659 | V3: RPKM_K01720 | W3: RPKM_K01847 | X3: RPKM_K01848 | Y3: RPKM_K01895 | Z3: RPKM_K01908 | AA3: RPKM_K02035 | AB3: RPKM_K02036 | AC3: RPKM_K02037 | AD3: RPKM_K02038 | AE3: RPKM_K02039 | AF3: RPKM_K02040 | AG3: RPKM_K02305 | AH3: RPKM_K02567 | AI3: RPKM_K02568 | AJ3: RPKM_K03385 | AK3: RPKM_K03821 | AL3: RPKM_K04561 | AM3: RPKM_K05973 | AN3: RPKM_K07636 | AO3: RPKM_K07657 | AP3: RPKM_K15864 | AQ3: RPKM_K15876 | AR3: RPKM_K22468
A4: CAN_1 | B4: 904.4525 | C4: 972.636 | D4: 729.6238 | E4: 272.7797 | F4: 815.7527 | G4: 1585.3367 | H4: 496.7919 | I4: 71.787 | J4: 375.2031 | K4: 3035.7739 | L4: 596.6019 | M4: 1369.1444 | N4: 1480.5106 | O4: 495.5382 | P4: 587.607 | Q4: 1419.8732 | R4: 1494.0556 | S4: 991.4249 | T4: 1.1043 | U4: 117.3052 | V4: 67.4792 | W4: 2626.3064 | X4: 446.8123 | Y4: 2493.7791 | Z4: 306.6751 | AA4: 1516.6178 | AB4: 1173.3851 | AC4: 1060.9703 | AD4: 934.0006 | AE4: 1365.438 | AF4: 1815.1513 | AG4: 974.8243 | AH4: 164.5199 | AI4: 319.3507 | AJ4: 620.6709 | AK4: 2359.1874 | AL4: 576.9433 | AM4: 317.0557 | AN4: 981.0954 | AO4: 1062.0938 | AP4: 755.5164 | AQ4: 164.4764 | AR4: 564.8224
A5: CAN_2 | B5: 1248.9799 | C5: 1038.2379 | D5: 879.3364 | E5: 175.317 | F5: 815.3265 | G5: 1528.5678 | H5: 501.7324 | I5: 146.4271 | J5: 243.9515 | K5: 3261.4528 | L5: 647.2754 | M5: 1330.4041 | N5: 1567.0751 | O5: 439.2576 | P5: 574.4758 | Q5: 1645.9293 | R5: 1534.0161 | S5: 1002.1421 | T5: 3.0721 | U5: 102.454 | V5: 46.3469 | W5: 2633.5043 | X5: 348.791 | Y5: 2607.816 | Z5: 343.3445 | AA5: 1394.5757 | AB5: 1159.3963 | AC5: 1021.0732 | AD5: 966.3193 | AE5: 1355.9082 | AF5: 1772.5301 | AG5: 1144.6988 | AH5: 206.9621 | AI5: 478.7059 | AJ5: 398.2349 | AK5: 2502.0573 | AL5: 616.5661 | AM5: 379.4192 | AN5: 960.7492 | AO5: 1136.8647 | AP5: 749.4066 | AQ5: 125.4074 | AR5: 521.8446
A6: CAN_3 | B6: 1203.8779 | C6: 1029.9123 | D6: 868.6243 | E6: 175.1574 | F6: 837.7137 | G6: 1555.535 | H6: 526.4188 | I6: 137.6126 | J6: 253.6653 | K6: 3175.5852 | L6: 640.9967 | M6: 1359.5403 | N6: 1563.3938 | O6: 441.8126 | P6: 593.958 | Q6: 1639.469 | R6: 1567.6628 | S6: 990.3911 | T6: 3.104 | U6: 104.8947 | V6: 53.0855 | W6: 2623.8542 | X6: 362.4298 | Y6: 2605.8338 | Z6: 332.8922 | AA6: 1482.5709 | AB6: 1192.7025 | AC6: 1051.9545 | AD6: 988.2476 | AE6: 1350.0344 | AF6: 1801.407 | AG6: 1162.4388 | AH6: 191.4959 | AI6: 465.8427 | AJ6: 406.4666 | AK6: 2450.8455 | AL6: 637.6067 | AM6: 389.5313 | AN6: 950.9208 | AO6: 1093.3496 | AP6: 759.815 | AQ6: 124.4907 | AR6: 533.0001
A7: CAN_4 | B7: 647.0253 | C7: 657.24 | D7: 718.4852 | E7: 366.9362 | F7: 419.5314 | G7: 698.6548 | H7: 288.5364 | I7: 58.4804 | J7: 527.221 | K7: 2523.3414 | L7: 419.8944 | M7: 1102.2654 | N7: 1371.0917 | O7: 362.8823 | P7: 789.1542 | Q7: 799.3874 | R7: 1127.8622 | S7: 1070.4784 | T7: 0 | U7: 165.7756 | V7: 157.9417 | W7: 1449.0153 | X7: 519.1235 | Y7: 1646.5663 | Z7: 346.7725 | AA7: 1747.9335 | AB7: 1025.6772 | AC7: 926.7924 | AD7: 747.2995 | AE7: 1179.4455 | AF7: 1655.3994 | AG7: 474.5206 | AH7: 174.2832 | AI7: 274.2411 | AJ7: 698.7391 | AK7: 2055.7446 | AL7: 542.054 | AM7: 306.4191 | AN7: 989.5364 | AO7: 839.4284 | AP7: 680.1832 | AQ7: 224.3756 | AR7: 1067.6322
A8: CAN_5 | B8: 538.4374 | C8: 554.4509 | D8: 686.4416 | E8: 349.4791 | F8: 216.8253 | G8: 338.4178 | H8: 184.3566 | I8: 47.6277 | J8: 467.599 | K8: 2162.2053 | L8: 419.9619 | M8: 1313.6933 | N8: 1167.1118 | O8: 277.7877 | P8: 692.4448 | Q8: 566.6734 | R8: 986.2563 | S8: 971.5176 | T8: 0 | U8: 156.6412 | V8: 181.4304 | W8: 1039.6818 | X8: 468.2768 | Y8: 1348.3563 | Z8: 363.9466 | AA8: 1575.5602 | AB8: 845.5874 | AC8: 670.5947 | AD8: 654.8874 | AE8: 935.8047 | AF8: 1273.5044 | AG8: 340.2402 | AH8: 236.1512 | AI8: 442.149 | AJ8: 296.5226 | AK8: 1504.2513 | AL8: 449.3578 | AM8: 589.1419 | AN8: 985.8048 | AO8: 895.7373 | AP8: 771.8277 | AQ8: 140.3157 | AR8: 1088.3153

Sheet Table S3_gene copies
A1: Table S3. Gene copy number of target genes per MAG
A2: K00376 is split into nosZ I and nosZ II columns.
A3: MAGs | B3: iterative ID | C3: Taxonomy | D3: copy number_K00023 | E3: copy number_K00362 | F3: copy number_K00363 | G3: copy number_K00368 | H3: copy number_K00370 | I3: copy number_K00371 | J3: copy number_K00374 | K3: copy number_nosZ I | L3: copy number_nosZ II | M3: copy number_K00626 | N3: copy number_K00634 | O3: copy number_K00688 | P3: copy number_K00700 | Q3: copy number_K00702 | R3: copy number_K00703 | S3: copy number_K00925 | T3: copy number_K00937 | U3: copy number_K01214 | V3: copy number_K01514 | W3: copy number_K01659 | X3: copy number_K01720 | Y3: copy number_K01847 | Z3: copy number_K01848 | AA3: copy number_K01895 | AB3: copy number_K01908 | AC3: copy number_K02035 | AD3: copy number_K02036 | AE3: copy number_K02037 | AF3: copy number_K02038 | AG3: copy number_K02039 | AH3: copy number_K02040 | AI3: copy number_K02305 | AJ3: copy number_K02567 | AK3: copy number_K02568 | AL3: copy number_K03385 | AM3: copy number_K03821 | AN3: copy number_K04561 | AO3: copy number_K05973 | AP3: copy number_K07636 | AQ3: copy number_K07657 | AR3: copy number_K15864 | AS3: copy number_K15876 | AT3: copy number_K22468
A4: CAN_1_bin.148 | B4: Dokdonella.13 | C4: =_xlfn.TEXTJOIN(";", TRUE,'Table S1_MAG quality'!C5:G5) | D4: 0 | E4: 0 | F4: 0 | G4: 0 | H4: 0 | I4: 0 | J4: 0 | K4: 0 | L4: 0 | M4: 1 | N4: 0 | O4: 0 | P4: 0 | Q4: 0 | R4: 0 | S4: 0 | T4: 1 | U4: 0 | V4: 0 | W4: 0 | X4: 0 | Y4: 0 | Z4: 0 | AA4: 0 | AB4: 0 | AC4: 0 | AD4: 1 | AE4: 1 | AF4: 1 | AG4: 1 | AH4: 1 | AI4: 0 | AJ4: 0 | AK4: 0 | AL4: 0 | AM4: 0 | AN4: 0 | AO4: 0 | AP4: 1 | AQ4: 1 | AR4: 0 | AS4: 0 | AT4: 0
A5: CAN_1_bin.174 | B5: UBA5532_m.1 | C5: =_xlfn.TEXTJOIN(";", TRUE,'Table S1_MAG quality'!C6:G6) | D5: 0 | E5: 0 | F5: 0 | G5: 0 | H5: 0 | I5: 0 | J5: 0 | K5: 0 | L5: 0 | M5: 0 | N5: 0 | O5: 0 | P5: 0 | Q5: 0 | R5: 0 | S5: 0 | T5: 0 | U5: 0 | V5: 0 | W5: 0 | X5: 0 | Y5: 0 | Z5: 0 | AA5: 0 | AB5: 0 | AC5: 0 | AD5: 0 | AE5: 0 | AF5: 0 | AG5: 0 | AH5: 0 | AI5: 0 | AJ5: 0 | AK5: 0 | AL5: 0 | AM5: 0 | AN5: 0 | AO5: 0 | AP5: 0 | AQ5: 0 | AR5: 0 | AS5: 0 | AT5: 0
A6: CAN_1_bin.177 | B6: midas_g_155.3 | C6: =_xlfn.TEXTJOIN(";", TRUE,'Table S1_MAG quality'!C7:G7) | D6: 0 | E6: 0 | F6: 0 | G6: 0 | H6: 0 | I6: 0 | J6: 0 | K6: 1 | L6: 0 | M6: 0 | N6: 0 | O6: 0 | P6: 0 | Q6: 0 | R6: 0 | S6: 0 | T6: 0 | U6: 0 | V6: 0 | W6: 0 | X6: 0 | Y6: 0 | Z6: 0 | AA6: 0 | AB6: 0 | AC6: 0 | AD6: 0 | AE6: 0 | AF6: 0 | AG6: 0 | AH6: 0 | AI6: 0 | AJ6: 0 | AK6: 0 | AL6: 0 | AM6: 0 | AN6: 0 | AO6: 0 | AP6: 0 | AQ6: 0 | AR6: 0 | AS6: 0 | AT6: 0
A7: CAN_1_bin.180 | B7: Bdellovibrio.13 | C7: =_xlfn.TEXTJOIN(";", TRUE,'Table S1_MAG quality'!C8:G8) | D7: 0 | E7: 0 | F7: 0 | G7: 0 | H7: 0 | I7: 0 | J7: 0 | K7: 0 | L7: 0 | M7: 0 | N7: 0 | O7: 0 | P7: 0 | Q7: 0 | R7: 0 | S7: 0 | T7: 0 | U7: 0 | V7: 0 | W7: 0 | X7: 0 | Y7: 0 | Z7: 0 | AA7: 0 | AB7: 0 | AC7: 0 | AD7: 0 | AE7: 0 | AF7: 0 | AG7: 0 | AH7: 0 | AI7: 0 | AJ7: 0 | AK7: 0 | AL7: 0 | AM7: 0 | AN7: 0 | AO7: 0 | AP7: 0 | AQ7: 0 | AR7: 0 | AS7: 0 | AT7: 0
A8: CAN_1_bin.195 | B8: UBA919_m.1 | C8: =_xlfn.TEXTJOIN(";", TRUE,'Table S1_MAG quality'!C9:G9) | D8: 0 | E8: 0 | F8: 0 | G8: 0 | H8: 0 | I8: 0 | J8: 0 | K8: 0 | L8: 0 | M8: 0 | N8: 0 | O8: 0 | P8: 0 | Q8: 0 | R8: 0 | S8: 0 | T8: 0 | U8: 0 | V8: 0 | W8: 0 | X8: 0 | Y8: 0 | Z8: 0 | AA8: 0 | AB8: 0 | AC8: 0 | AD8: 0 | AE8: 0 | AF8: 0 | AG8: 0 | AH8: 0 | AI8: 0 | AJ8: 0 | AK8: 0 | AL8: 0 | AM8: 0 | AN8: 0 | AO8: 0 | AP8: 0 | AQ8: 0 | AR8: 0 | AS8: 0 | AT8: 0
A9: CAN_1_bin.2 | B9: B-1AR_m.1 | C9: =_xlfn.TEXTJOIN(";", TRUE,'Table S1_MAG quality'!C10:G10) | D9: 0 | E9: 0 | F9: 0 | G9: 0 | H9: 0 | I9: 0 | J9: 0 | K9: 0 | L9: 0 | M9: 0 | N9: 0 | O9: 0 | P9: 0 | Q9: 0 | R9: 0 | S9: 0 | T9: 0 | U9: 0 | V9: 0 | W9: 0 | X9: 0 | Y9: 0 | Z9: 0 | AA9: 0 | AB9: 0 | AC9: 0 | AD9: 0 | AE9: 0 | AF9: 0 | AG9: 0 | AH9: 0 | AI9: 0 | AJ9: 0 | AK9: 0 | AL9: 0 | AM9: 0 | AN9: 0 | AO9: 0 | AP9: 0 | AQ9: 0 | AR9: 0 | AS9: 0 | AT9: 0
A10: CAN_1_bin.210 | B10: Dokdonella.14 | C10: =_xlfn.TEXTJOIN(";", TRUE,'Table S1_MAG quality'!C11:G11) | D10: 0 | E10: 0 | F10: 0 | G10: 0 | H10: 0 | I10: 0 | J10: 0 | K10: 0 | L10: 0 | M10: 0 | N10: 0 | O10: 0 | P10: 0 | Q10: 0 | R10: 0 | S10: 0 | T10: 0 | U10: 0 | V10: 0 | W10: 0 | X10: 0 | Y10: 0 | Z10: 0 | AA10: 0 | AB10: 0 | AC10: 0 | AD10: 0 | AE10: 0 | AF10: 0 | AG10: 0 | AH10: 0 | AI10: 0 | AJ10: 0 | AK10: 0 | AL10: 0 | AM10: 0 | AN10: 0 | AO10: 0 | AP10: 0 | AQ10: 0 | AR10: 0 | AS10: 0 | AT10: 0
A11: CAN_1_bin.48 | B11: GWB1-50-10_m.1 | C11: =_xlfn.TEXTJOIN(";", TRUE,'Table S1_MAG quality'!C12:G12) | D11: 0 | E11: 0 | F11: 0 | G11: 0 | H11: 0 | I11: 0 | J11: 0 | K11: 0 | L11: 0 | M11: 0 | N11: 0 | O11: 0 | P11: 0 | Q11: 0 | R11: 0 | S11: 0 | T11: 0 | U11: 0 | V11: 0 | W11: 0 | X11: 0 | Y11: 0 | Z11: 0 | AA11: 0 | AB11: 0 | AC11: 0 | AD11: 0 | AE11: 0 | AF11: 0 | AG11: 0 | AH11: 0 | AI11: 0 | AJ11: 0 | AK11: 0 | AL11: 0 | AM11: 0 | AN11: 0 | AO11: 0 | AP11: 0 | AQ11: 0 | AR11: 0 | AS11: 0 | AT11: 0
A12: CAN_1_bin.5 | B12: UBA1573_m.1 | C12: =_xlfn.TEXTJOIN(";", TRUE,'Table S1_MAG quality'!C13:G13) | D12: 1 | E12: 0 | F12: 0 | G12: 0 | H12: 0 | I12: 0 | J12: 0 | K12: 0 | L12: 0 | M12: 0 | N12: 0 | O12: 0 | P12: 0 | Q12: 0 | R12: 0 | S12: 1 | T12: 0 | U12: 0 | V12: 0 | W12: 0 | X12: 0 | Y12: 0 | Z12: 0 | AA12: 0 | AB12: 0 | AC12: 0 | AD12: 0 | AE12: 0 | AF12: 0 | AG12: 0 | AH12: 0 | AI12: 0 | AJ12: 0 | AK12: 0 | AL12: 0 | AM12: 1 | AN12: 0 | AO12: 0 | AP12: 0 | AQ12: 0 | AR12: 0 | AS12: 0 | AT12: 0
A13: CAN_1_bin.77 | B13: UBA5066_m.1 | C13: =_xlfn.TEXTJOIN(";", TRUE,'Table S1_MAG quality'!C14:G14) | D13: 0 | E13: 0 | F13: 0 | G13: 0 | H13: 0 | I13: 0 | J13: 0 | K13: 0 | L13: 1 | M13: 0 | N13: 0 | O13: 0 | P13: 0 | Q13: 0 | R13: 0 | S13: 0 | T13: 0 | U13: 0 | V13: 0 | W13: 0 | X13: 0 | Y13: 0 | Z13: 1 | AA13: 0 | AB13: 0 | AC13: 0 | AD13: 0 | AE13: 0 | AF13: 0 | AG13: 0 | AH13: 0 | AI13: 0 | AJ13: 0 | AK13: 0 | AL13: 0 | AM13: 0 | AN13: 0 | AO13: 0 | AP13: 0 | AQ13: 0 | AR13: 0 | AS13: 0 | AT13: 0
A14: CAN_1_bin.84 | B14: CFX2_m.1 | C14: =_xlfn.TEXTJOIN(";", TRUE,'Table S1_MAG quality'!C15:G15) | D14: 0 | E14: 0 | F14: 0 | G14: 1 | H14: 0 | I14: 0 | J14: 0 | K14: 0 | L14: 0 | M14: 2 | N14: 0 | O14: 0 | P14: 0 | Q14: 0 | R14: 0 | S14: 0 | T14: 0 | U14: 0 | V14: 0 | W14: 0 | X14: 0 | Y14: 0 | Z14: 0 | AA14: 0 | AB14: 0 | AC14: 0 | AD14: 1 | AE14: 1 | AF14: 1 | AG14: 0 | AH14: 0 | AI14: 0 | AJ14: 0 | AK14: 0 | AL14: 0 | AM14: 0 | AN14: 0 | AO14: 0 | AP14: 0 | AQ14: 0 | AR14: 0 | AS14: 0 | AT14: 0
A15: CAN_1_bin.98 | B15: Ca_Accumulibacter.23 | C15: =_xlfn.TEXTJOIN(";", TRUE,'Table S1_MAG quality'!C16:G16) | D15: 0 | E15: 1 | F15: 1 | G15: 0 | H15: 0 | I15: 0 | J15: 0 | K15: 0 | L15: 1 | M15: 2 | N15: 0 | O15: 1 | P15: 0 | Q15: 0 | R15: 1 | S15: 0 | T15: 0 | U15: 0 | V15: 0 | W15: 0 | X15: 0 | Y15: 0 | Z15: 0 | AA15: 0 | AB15: 0 | AC15: 0 | AD15: 0 | AE15: 0 | AF15: 0 | AG15: 0 | AH15: 1 | AI15: 0 | AJ15: 0 | AK15: 0 | AL15: 0 | AM15: 2 | AN15: 0 | AO15: 0 | AP15: 0 | AQ15: 0 | AR15: 0 | AS15: 0 | AT15: 1
... A279: coasm_bin.93 | B279: midas_g_4351.1 | C279: =_xlfn.TEXTJOIN(";", TRUE,'Table S1_MAG quality'!C280:G280) | D279: 1 | E279: 0 | F279: 0 | G279: 0 | H279: 0 | I279: 0 | J279: 0 | K279: 0 | L279: 0 | M279: 9 | N279: 0 | O279: 0 | P279: 0 | Q279: 0 | R279: 0 | S279: 0 | T279: 1 | U279: 0 | V279: 0 | W279: 0 | X279: 0 | Y279: 1 | Z279: 0 | AA279: 1 | AB279: 0 | AC279: 6 | AD279: 1 | AE279: 1 | AF279: 2 | AG279: 1 | AH279: 1 | AI279: 0 | AJ279: 0 | AK279: 0 | AL279: 0 | AM279: 3 | AN279: 0 | AO279: 1 | AP279: 1 | AQ279: 1 | AR279: 0 | AS279: 0 | AT279: 1

Sheet Table S4_nosZ_genecopy_type
A1: Table S4. Mags with NosZ genes, type and copy number
A2: Rerference tree
A3: MAG | B3: MAG iteration ID | C3: genus | D3: nosZ_copies | E3: cladeI | F3: cladeII | G3: cladeIII | H3: clade_call | I3: best_hmm_score
A4: CAN_1_bin.177 | B4: midas_g_155.3_ma | C4: Pararhodobacter | D4: 1 | E4: 1 | F4: 0 | G4: 0 | H4: I | I4: 755.8
A5: CAN_1_bin.77 | B5: UBA5066.1_m | C5: UBA5066 | D5: 1 | E5: 0 | F5: 1 | G5: 0 | H5: II | I5: 716.6
A6: CAN_1_bin.98 | B6: Ca_Accumulibacter.23_ma | C6: Accumulibacter | D6: 1 | E6: 0 | F6: 1 | G6: 0 | H6: II | I6: 714.7
A7: CAN_2_bin.173 | B7: JACDQM01.1_m | C7: JACDQM01 | D7: 1 | E7: 1 | F7: 0 | G7: 0 | H7: I | I7: 515.2
A8: CAN_2_bin.176 | B8: UBA5066.2_m | C8: UBA5066 | D8: 1 | E8: 0 | F8: 1 | G8: 0 | H8: II | I8: 725.8
A9: CAN_2_bin.23 | B9: Zoogloea.11_ma | C9: Zoogloea | D9: 1 | E9: 1 | F9: 0 | G9: 0 | H9: I | I9: 747.4
A10: CAN_2_bin.6 | B10: Denitratisoma.2_ma | C10: Desulfobacillus | D10: 1 | E10: 0 | F10: 1 | G10: 0 | H10: II | I10: 727
A11: CAN_2_bin.66 | B11: JACTMZ01.1_m | C11: JACTMZ01 | D11: 1 | E11: 0 | F11: 1 | G11: 0 | H11: II | I11: 691.3
A12: CAN_3_bin.10 | B12: Rhodobacter.13_ma | C12: JAAKGP01 | D12: 1 | E12: 1 | F12: 0 | G12: 0 | H12: I | I12: 745.8
A13: CAN_3_bin.203 | B13: JAEULV01.1_m | C13: JAEULV01 | D13: 1 | E13: 0 | F13: 1 | G13: 0 | H13: II | I13: 701
A14: CAN_3_bin.205 | B14: Niabella.2_ma | C14: Niabella | D14: 1 | E14: 0 | F14: 1 | G14: 0 | H14: II | I14: 720
A15: CAN_3_bin.208 | B15: Sulfuritalea.5_ma | C15: Azospira_A | D15: 1 | E15: 0 | F15: 1 | G15: 0 | H15: II | I15: 724.4
... A125: coasm_bin.61 | B125: midas_g_9628.1_ma | C125: UBA1930 | D125: 1 | E125: 0 | F125: 1 | G125: 0 | H125: II | I125: 721

Sheet Table S5 _ppk_ACC
A1: Table S4. Mags with NosZ genes, type and copy number
A2: Rerference tree
A3: MAG | B3: MAG iteration ID | C3: ppk1_type | D3: proposed_species | E3: SH-aLRT/UFBoot | F3: top_pid | G3: nearest_reference | H3: note
A4: CAN_1_bin.98 | C4: Type I (unclassified) | E4: / | F4: 87.7% (IE) | G4: Candidatus Accumulibacter sp. UBA11064 | H4: Type I, divergent/novel (max id ~88%, no established clade)
A5: CAN_4_bin.225 | C5: no ppk1 recovered | H5: Accumulibacter, ~92% size but 99 contigs (N50 85 kb); no ppk1 ORF assembled - gene likely split across a contig break (KO K00937=1 = sub-HMM fragment, not a full gene)
A6: CAN_4_bin.64 | C6: Type I (unclassified) | E6: 100/100 | F6: 99.1% (un) | G6: Candidatus Accumulibacter sp. UBA11064 | H6: Type I, unclassified (≈UBA11064, 99% id; ~88% to named clades)
A7: coasm_bin.185 | C7: IA | D7: Ca. Accumulibacter regalis | E7: 99.5/100 | F7: 100.0% (IA) | G7: Candidatus Accumulibacter phosphatis CANDO_1; Candidatus Accumulibacter phosphatis UW3; UCB HP1-ppk2 -02 | H7: clade IA
A8: coasm_bin.250 | C8: IC | D8: Ca. Accumulibacter delftensis | E8: 100/100 | F8: 99.8% (IC) | G8: Ca. A. delftensis; Inoc_ppk1_020 | H8: clade IC (delftensis vs meliphilus: closest delftensis)
A9: coasm_bin.347 | C9: IIA | D9: Ca. Accumulibacter phosphatis | E9: 81.9/99 | F9: 99.4% (IIA) | G9: Candidatus Accumulibacter phosphatis UW1; Candidatus Accumulibacter phosphatis UW9-POB; Candidatus Accumulibacter phosphatis UW5 | H9: clade IIA (phosphatis lineage, UW1 type strain)
A10: coasm_bin.476 | C10: no ppk1 recovered | H10: Accumulibacter, ~55% complete (2.2 Mb, 4 contigs); ppk1 not recovered in the assembly
