Workbook

Sheet Table S1_MAG quality
A1: Table S1. MAG quality
A2: Empty template for MAG quality, taxonomy, assembly statistics, and relative abundance across CAN_1–CAN_5.
A3: MAG bin name | B3: MAG iteration ID | C3: Phylum | D3: Class | E3: Order | F3: Family | G3: Genus | H3: Compl. (%) | I3: Contamin (%) | J3: Genome size | K3: Contig number | L3: GC | M3: N50 (bp) | N3: rel_abun in CAN_1 | O3: rel_abun in CAN_2 | P3: rel_abun in CAN_3 | Q3: rel_abun in CAN_4 | R3: rel_abun in CAN_5 | S3: Taxonomy | T3: average Total abundance
A4: CAN_1_bin.148 | B4: Dokdonella.5 | C4: Pseudomonadota | D4: Gammaproteobacteria | E4: Xanthomonadales | F4: Rhodanobacteraceae | G4: Dokdonella | H4: 95.69 | I4: 7.58 | J4: 4210296 | K4: 46 | L4: 0.69 | M4: 415687 | N4: 0.003611728 | O4: 0.004485683 | P4: 0.004445603 | Q4: 0.000991 | R4: 0.000191 | S4: p__Pseudomonadota; c__Gammaproteobacteria; o__Xanthomonadales; f__Rhodanobacteraceae; g__Dokdonella | T4: =AVERAGE('Table S1_MAG quality'!$N4:$R4)
A5: CAN_1_bin.174 | B5: Gracilibacteria.30 | C5: Patescibacteria | D5: JAEDAM01 | E5: BD1-5 | F5: UBA2023 | G5: UBA5532 | H5: 97.22 | I5: 1.35 | J5: 1166702 | K5: 1 | L5: 0.43 | M5: 1166702 | N5: 0.03028026 | O5: 0.007001495 | P5: 0.010296311 | Q5: 0.005247412 | R5: 0.00345912 | S5: p__Patescibacteria; c__; o__; f__; g__ | T5: =AVERAGE('Table S1_MAG quality'!$N5:$R5)
A6: CAN_1_bin.177 | B6: Pararhodobacter.1_m | C6: Pseudomonadota | D6: Alphaproteobacteria | E6: Rhodobacterales | F6: Rhodobacteraceae | G6: Pararhodobacter | H6: 100 | I6: 0.15 | J6: 4385690 | K6: 2 | L6: 0.68 | M6: 3311625 | N6: 0.003267175 | O6: 0.002588946 | P6: 0.002613809 | Q6: 0.003671736 | R6: 0.001538334 | S6: p__Pseudomonadota; c__Alphaproteobacteria; o__Rhodobacterales; f__Rhodobacteraceae; g__Pararhodobacter | T6: =AVERAGE('Table S1_MAG quality'!$N6:$R6)
A7: CAN_1_bin.180 | B7: Bdellovibrio.13 | C7: Bdellovibrionota | D7: Bdellovibrionia | E7: Bdellovibrionales | F7: Bdellovibrionaceae | G7: UBA2316 | H7: 99.98 | I7: 0.52 | J7: 4039223 | K7: 20 | L7: 0.34 | M7: 593163 | N7: 0.002546397 | O7: 0.000756 | P7: 0.001003109 | Q7: 0.000226 | R7: 3.57e-05 | S7: p__Bdellovibrionota; c__Bdellovibrionia; o__Bdellovibrionales; f__Bdellovibrionaceae; g__ | T7: =AVERAGE('Table S1_MAG quality'!$N7:$R7)
A8: CAN_1_bin.195 | B8: Ca_Falkowbacteria.7 | C8: Patescibacteria | D8: ABY1 | E8: BM507 | F8: UBA917 | G8: UBA919 | H8: 97.28 | I8: 1.45 | J8: 894103 | K8: 1 | L8: 0.4 | M8: 894103 | N8: 0.00320921 | O8: 0.000658 | P8: 0.001034346 | Q8: 0.004408273 | R8: 0.001836505 | S8: p__Patescibacteria; c__; o__; f__; g__ | T8: =AVERAGE('Table S1_MAG quality'!$N8:$R8)
A9: CAN_1_bin.2 | B9: Ignavibacteria.5 | C9: Bacteroidota | D9: Ignavibacteria | E9: SJA-28 | F9: B-1AR | H9: 98.74 | I9: 1.2 | J9: 3126569 | K9: 1 | L9: 0.35 | M9: 3126569 | N9: 0.00189427 | O9: 0.000461 | P9: 0.000817 | Q9: 0.005366112 | R9: 0.005835915 | S9: p__Bacteroidota; c__Ignavibacteria; o__; f__; g__ | T9: =AVERAGE('Table S1_MAG quality'!$N9:$R9)
A10: CAN_1_bin.210 | B10: Dokdonella.14 | C10: Pseudomonadota | D10: Gammaproteobacteria | E10: Xanthomonadales | F10: Rhodanobacteraceae | G10: Dokdonella | H10: 99.55 | I10: 0.45 | J10: 3941745 | K10: 13 | L10: 0.69 | M10: 728973 | N10: 0.009766223 | O10: 0.013387657 | P10: 0.013225006 | Q10: 0.011006405 | R10: 0.001762958 | S10: p__Pseudomonadota; c__Gammaproteobacteria; o__Xanthomonadales; f__Rhodanobacteraceae; g__Dokdonella | T10: =AVERAGE('Table S1_MAG quality'!$N10:$R10)
A11: CAN_1_bin.48 | B11: Paceibacteria.1_m | C11: Patescibacteria | D11: Paceibacteria | E11: UBA6257 | F11: GWB1-50-10 | H11: 100 | I11: 0.1 | J11: 668260 | K11: 1 | L11: 0.44 | M11: 668260 | N11: 0.002868404 | O11: 0.00263992 | P11: 0.002592972 | Q11: 4.33e-05 | R11: 3.68e-05 | S11: p__Patescibacteria; c__Paceibacteria; o__; f__; g__ | T11: =AVERAGE('Table S1_MAG quality'!$N11:$R11)
A12: CAN_1_bin.5 | B12: Micavibrionaceae.1_m | C12: Pseudomonadota | D12: Alphaproteobacteria | E12: Micavibrionales | F12: Micavibrionaceae | G12: UBA1573 | H12: 100 | I12: 2.92 | J12: 2295354 | K12: 2 | L12: 0.45 | M12: 1600197 | N12: 0.004824322 | O12: 0.003347207 | P12: 0.003304787 | Q12: 0.013089252 | R12: 0.017626096 | S12: p__Pseudomonadota; c__Alphaproteobacteria; o__Micavibrionales; f__Micavibrionaceae; g__ | T12: =AVERAGE('Table S1_MAG quality'!$N12:$R12)
A13: CAN_1_bin.77 | B13: Thermoanaerobaculia.1_m | C13: Acidobacteriota | D13: Thermoanaerobaculia | E13: UBA5066 | F13: UBA5066 | G13: UBA5066 | H13: 97.68 | I13: 0.28 | J13: 5985155 | K13: 4 | L13: 0.7 | M13: 1686115 | N13: 0.010532733 | O13: 0.012878474 | P13: 0.012526772 | Q13: 0.019967309 | R13: 0.0495223 | S13: p__Acidobacteriota; c__Thermoanaerobaculia; o__; f__; g__ | T13: =AVERAGE('Table S1_MAG quality'!$N13:$R13)
A14: CAN_1_bin.84 | B14: Phototrophicaceae.1_m | C14: Chloroflexota | D14: Anaerolineae | E14: Aggregatilineales | F14: Phototrophicaceae | G14: CFX2 | H14: 96.16 | I14: 2.61 | J14: 6398485 | K14: 8 | L14: 0.55 | M14: 3749479 | N14: 0.005559483 | O14: 0.004930177 | P14: 0.005031585 | Q14: 0.001603134 | R14: 0.000277 | S14: p__Chloroflexota; c__Anaerolineae; o__Aggregatilineales; f__Phototrophicaceae; g__ | T14: =AVERAGE('Table S1_MAG quality'!$N14:$R14)
A15: CAN_1_bin.98 | B15: Ca_Accumulibacter.23 | C15: Pseudomonadota | D15: Gammaproteobacteria | E15: Burkholderiales | F15: Rhodocyclaceae | G15: Accumulibacter | H15: 100 | I15: 0.19 | J15: 5022376 | K15: 6 | L15: 0.65 | M15: 3573482 | N15: 0.033631117 | O15: 0.02515896 | P15: 0.02536908 | Q15: 0.11391873 | R15: 0.041523786 | S15: p__Pseudomonadota; c__Gammaproteobacteria; o__Burkholderiales; f__Rhodocyclaceae; g__Accumulibacter | T15: =AVERAGE('Table S1_MAG quality'!$N15:$R15)
A16: CAN_2_bin.125 | B16: Pseudoxanthomonas_A.1_m | C16: Pseudomonadota | D16: Gammaproteobacteria | E16: Xanthomonadales | F16: Xanthomonadaceae | G16: Pseudoxanthomonas_A | H16: 99.78 | I16: 1.71 | J16: 3440139 | K16: 25 | L16: 0.68 | M16: 222642 | N16: 0.02209988 | O16: 0.03671151 | P16: 0.035104854 | Q16: 0.00059 | R16: 0.000126 | S16: p__Pseudomonadota; c__Gammaproteobacteria; o__Xanthomonadales; f__Xanthomonadaceae; g__Pseudoxanthomonas_A | T16: =AVERAGE('Table S1_MAG quality'!$N16:$R16)
A17: CAN_2_bin.151 | B17: Brevundimonas.4 | C17: Pseudomonadota | D17: Alphaproteobacteria | E17: Caulobacterales | F17: Caulobacteraceae | G17: Brevundimonas | H17: 99.99 | I17: 1.73 | J17: 2857677 | K17: 2 | L17: 0.68 | M17: 2456369 | N17: 0.003811263 | O17: 0.006971384 | P17: 0.006640263 | Q17: 0.000494 | R17: 0.001051654 | S17: p__Pseudomonadota; c__Alphaproteobacteria; o__Caulobacterales; f__Caulobacteraceae; g__Brevundimonas | T17: =AVERAGE('Table S1_MAG quality'!$N17:$R17)
A18: CAN_2_bin.159 | B18: Pseudoxanthomonas.23 | C18: Pseudomonadota | D18: Gammaproteobacteria | E18: Xanthomonadales | F18: Xanthomonadaceae | G18: Pseudoxanthomonas | H18: 100 | I18: 0.02 | J18: 2816656 | K18: 3 | L18: 0.7 | M18: 1658373 | N18: 0.012928113 | O18: 0.00873372 | P18: 0.008937194 | Q18: 0.02519797 | R18: 0.007934008 | S18: p__Pseudomonadota; c__Gammaproteobacteria; o__Xanthomonadales; f__Xanthomonadaceae; g__Pseudoxanthomonas | T18: =AVERAGE('Table S1_MAG quality'!$N18:$R18)
A19: CAN_2_bin.173 | B19: Burkholderiaceae.1_m | C19: Pseudomonadota | D19: Gammaproteobacteria | E19: Burkholderiales | F19: Burkholderiaceae | G19: JACDQM01 | H19: 88.51 | I19: 3.03 | J19: 3870350 | K19: 145 | L19: 0.69 | M19: 37630 | N19: 0.000685 | O19: 0.001854193 | P19: 0.001708084 | Q19: 0.000201 | R19: 0.000158 | S19: p__Pseudomonadota; c__Gammaproteobacteria; o__Burkholderiales; f__Burkholderiaceae; g__ | T19: =AVERAGE('Table S1_MAG quality'!$N19:$R19)
A20: CAN_2_bin.176 | B20: Thermoanaerobaculia.2_m | C20: Acidobacteriota | D20: Thermoanaerobaculia | E20: UBA5066 | F20: UBA5066 | G20: UBA5066 | H20: 95.76 | I20: 0.52 | J20: 5834731 | K20: 4 | L20: 0.7 | M20: 2059594 | N20: 0.004208347 | O20: 0.007036818 | P20: 0.006669267 | Q20: 0.000464 | R20: 0.000399 | S20: p__Acidobacteriota; c__Thermoanaerobaculia; o__; f__; g__ | T20: =AVERAGE('Table S1_MAG quality'!$N20:$R20)
A21: CAN_2_bin.23 | B21: Zoogloea.11 | C21: Pseudomonadota | D21: Gammaproteobacteria | E21: Burkholderiales | F21: Rhodocyclaceae | G21: Zoogloea | H21: 96.04 | I21: 0.54 | J21: 4657897 | K21: 32 | L21: 0.66 | M21: 295469 | N21: 0.005985822 | O21: 0.008841831 | P21: 0.00836177 | Q21: 0.00049 | R21: 0.000638 | S21: p__Pseudomonadota; c__Gammaproteobacteria; o__Burkholderiales; f__Rhodocyclaceae; g__Zoogloea | T21: =AVERAGE('Table S1_MAG quality'!$N21:$R21)
A22: CAN_2_bin.6 | B22: Desulfobacillus.1_m | C22: Pseudomonadota | D22: Gammaproteobacteria | E22: Burkholderiales | F22: Rhodocyclaceae | G22: Desulfobacillus | H22: 99.7 | I22: 0.37 | J22: 3163088 | K22: 4 | L22: 0.65 | M22: 950453 | N22: 0.017174284 | O22: 0.006393228 | P22: 0.007236849 | Q22: 0.007495629 | R22: 0.000318 | S22: p__Pseudomonadota; c__Gammaproteobacteria; o__Burkholderiales; f__Rhodocyclaceae; g__Desulfobacillus | T22: =AVERAGE('Table S1_MAG quality'!$N22:$R22)
A23: CAN_2_bin.66 | B23: Chthoniobacterales.1_m | C23: Verrucomicrobiota | D23: Verrucomicrobiae | E23: Chthoniobacterales | F23: JACTMZ01 | G23: JACTMZ01 | H23: 87.35 | I23: 1.04 | J23: 2784204 | K23: 69 | L23: 0.63 | M23: 77074 | N23: 0.000982 | O23: 0.001388278 | P23: 0.001405915 | Q23: 0.000492 | R23: 0.000224 | S23: p__Verrucomicrobiota; c__Verrucomicrobiae; o__Chthoniobacterales; f__; g__ | T23: =AVERAGE('Table S1_MAG quality'!$N23:$R23)
... A51: CAN_4_bin.35 | B51: Brevundimonas.7 | C51: Pseudomonadota | D51: Alphaproteobacteria | E51: Caulobacterales | F51: Caulobacteraceae | G51: Brevundimonas | H51: 100 | I51: 0.06 | J51: 2759345 | K51: 3 | L51: 0.66 | M51: 2730425 | N51: 0.000416 | O51: 0.00021 | P51: 0.000243 | Q51: 0.004082246 | R51: 0.000286 | S51: p__Pseudomonadota; c__Alphaproteobacteria; o__Caulobacterales; f__Caulobacteraceae; g__Brevundimonas | T51: =AVERAGE('Table S1_MAG quality'!$N51:$R51)
A52: CAN_4_bin.38 | B52: Salinispiraceae.1_m | C52: Spirochaetota | D52: Spirochaetia | E52: DSM-27196 | F52: Salinispiraceae | H52: 65.19 | I52: 0.7 | J52: 2595407 | K52: 45 | L52: 0.53 | M52: 79947 | N52: 0.00017 | O52: 0.000168 | P52: 0.000172 | Q52: 0.00118189 | R52: 4.51e-05 | S52: p__Spirochaetota; c__Spirochaetia; o__; f__Salinispiraceae; g__ | T52: =AVERAGE('Table S1_MAG quality'!$N52:$R52)
A53: CAN_4_bin.44 | B53: Mesorhizobium.22 | C53: Pseudomonadota | D53: Alphaproteobacteria | E53: Rhizobiales | F53: Rhizobiaceae | G53: DUSC01 | H53: 99.99 | I53: 0.07 | J53: 5523224 | K53: 5 | L53: 0.67 | M53: 1873950 | N53: 0.000536 | O53: 0.00048 | P53: 0.000503 | Q53: 0.001886164 | R53: 0.002068712 | S53: p__Pseudomonadota; c__Alphaproteobacteria; o__Rhizobiales; f__Rhizobiaceae; g__ | T53: =AVERAGE('Table S1_MAG quality'!$N53:$R53)
A54: CAN_4_bin.62 | B54: Anaerolineaceae.1_m | C54: Chloroflexota | D54: Anaerolineae | E54: Anaerolineales | F54: Anaerolineaceae | G54: JARKPB01 | H54: 55.96 | I54: 2.44 | J54: 1992954 | K54: 83 | L54: 0.6 | M54: 31753 | N54: 0.000158 | O54: 0.000132 | P54: 0.000139 | Q54: 0.001276129 | R54: 0.000329 | S54: p__Chloroflexota; c__Anaerolineae; o__Anaerolineales; f__Anaerolineaceae; g__ | T54: =AVERAGE('Table S1_MAG quality'!$N54:$R54)
A55: CAN_4_bin.64 | B55: Accumulibacter.2_m | C55: Pseudomonadota | D55: Gammaproteobacteria | E55: Burkholderiales | F55: Rhodocyclaceae | G55: Accumulibacter | H55: 79.98 | I55: 1.84 | J55: 3842927 | K55: 53 | L55: 0.64 | M55: 109616 | N55: 0.005256289 | O55: 0.002262134 | P55: 0.002572883 | Q55: 0.009598464 | R55: 0.003685772 | S55: p__Pseudomonadota; c__Gammaproteobacteria; o__Burkholderiales; f__Rhodocyclaceae; g__Accumulibacter | T55: =AVERAGE('Table S1_MAG quality'!$N55:$R55)
A56: CAN_4_bin.70 | B56: Phototrophicaceae.2_m | C56: Chloroflexota | D56: Anaerolineae | E56: Aggregatilineales | F56: Phototrophicaceae | G56: JAIOHN01 | H56: 73.66 | I56: 1.16 | J56: 4082294 | K56: 54 | L56: 0.62 | M56: 132652 | N56: 0.000228 | O56: 0.000145 | P56: 0.000158 | Q56: 0.00108192 | R56: 0.0005 | S56: p__Chloroflexota; c__Anaerolineae; o__Aggregatilineales; f__Phototrophicaceae; g__ | T56: =AVERAGE('Table S1_MAG quality'!$N56:$R56)
A57: CAN_4_bin.72 | B57: Competibacter_A.1_m | C57: Pseudomonadota | D57: Gammaproteobacteria | E57: Competibacterales | F57: Competibacteraceae | G57: Competibacter_A | H57: 61.54 | I57: 5.05 | J57: 3004766 | K57: 112 | L57: 0.59 | M57: 39667 | N57: 0.010135044 | O57: 0.010248994 | P57: 0.010369587 | Q57: 0.004742864 | R57: 0.002621284 | S57: p__Pseudomonadota; c__Gammaproteobacteria; o__Competibacterales; f__Competibacteraceae; g__Competibacter_A | T57: =AVERAGE('Table S1_MAG quality'!$N57:$R57)
A58: CAN_4_bin.76 | B58: Dojkabacteria.1_m | C58: Patescibacteria | D58: Dojkabacteria | E58: J137 | F58: J137 | G58: Brojett037 | H58: 53.34 | I58: 0.39 | J58: 623697 | K58: 23 | L58: 0.33 | M58: 33654 | N58: 7.04e-05 | O58: 3.83e-05 | P58: 4.6e-05 | Q58: 0.000267 | R58: 1.27e-05 | S58: p__Patescibacteria; c__Dojkabacteria; o__; f__; g__ | T58: =AVERAGE('Table S1_MAG quality'!$N58:$R58)
A59: CAN_4_bin.92 | B59: Ca_Flexifilum.1 | C59: Chloroflexota | D59: Anaerolineae | E59: Aggregatilineales | F59: Phototrophicaceae | G59: Flexifilum | H59: 84.51 | I59: 6.83 | J59: 3994020 | K59: 91 | L59: 0.63 | M59: 86287 | N59: 0.000314 | O59: 0.000262 | P59: 0.000267 | Q59: 0.000933 | R59: 0.001900647 | S59: p__Chloroflexota; c__Anaerolineae; o__Aggregatilineales; f__Phototrophicaceae; g__Flexifilum | T59: =AVERAGE('Table S1_MAG quality'!$N59:$R59)
A60: CAN_5_bin.1 | B60: Rhabdaerophilum.1_m | C60: Pseudomonadota | D60: Alphaproteobacteria | E60: Rhizobiales | F60: Beijerinckiaceae | G60: Rhabdaerophilum | H60: 100 | I60: 0.04 | J60: 3153730 | K60: 1 | L60: 0.64 | M60: 3153730 | N60: 0.000541 | O60: 0.00044 | P60: 0.000463 | Q60: 0.000902 | R60: 0.003058194 | S60: p__Pseudomonadota; c__Alphaproteobacteria; o__Rhizobiales; f__Beijerinckiaceae; g__Rhabdaerophilum | T60: =AVERAGE('Table S1_MAG quality'!$N60:$R60)
A61: CAN_5_bin.100 | B61: Ignavibacteriaceae.1_m | C61: Bacteroidota | D61: Ignavibacteria | E61: Ignavibacteriales | F61: Ignavibacteriaceae | G61: JAEXTR01 | H61: 81.06 | I61: 0.18 | J61: 3252921 | K61: 5 | L61: 0.44 | M61: 840523 | N61: 0.001031642 | O61: 0.00087 | P61: 0.00093 | Q61: 0.001476168 | R61: 0.003898476 | S61: p__Bacteroidota; c__Ignavibacteria; o__Ignavibacteriales; f__Ignavibacteriaceae; g__ | T61: =AVERAGE('Table S1_MAG quality'!$N61:$R61)
A62: CAN_5_bin.106 | B62: Ca_Competibacter.139 | C62: Pseudomonadota | D62: Gammaproteobacteria | E62: Competibacterales | F62: Competibacteraceae | G62: Competibacter | H62: 92.13 | I62: 4.17 | J62: 2984512 | K62: 51 | L62: 0.62 | M62: 105487 | N62: 0.26809792 | O62: 0.26609695 | P62: 0.27174007 | Q62: 0.11192626 | R62: 0.065415 | S62: p__Pseudomonadota; c__Gammaproteobacteria; o__Competibacterales; f__Competibacteraceae; g__Competibacter | T62: =AVERAGE('Table S1_MAG quality'!$N62:$R62)
A63: CAN_5_bin.112 | B63: Terrimonas.22 | C63: Bacteroidota | D63: Bacteroidia | E63: Chitinophagales | F63: Chitinophagaceae | G63: JJ008 | H63: 100 | I63: 0.05 | J63: 4028776 | K63: 1 | L63: 0.42 | M63: 4028776 | N63: 0.000297 | O63: 0.000115 | P63: 0.000152 | Q63: 0.007590076 | R63: 0.027768152 | S63: p__Bacteroidota; c__Bacteroidia; o__Chitinophagales; f__Chitinophagaceae; g__ | T63: =AVERAGE('Table S1_MAG quality'!$N63:$R63)
A64: CAN_5_bin.145 | B64: Bacteroidia.19 | C64: Bacteroidota | D64: Bacteroidia | E64: J057 | F64: J057 | G64: JAAFHL01 | H64: 98.65 | I64: 0.1 | J64: 4785324 | K64: 1 | L64: 0.49 | M64: 4785324 | N64: 0.000541 | O64: 0.000451 | P64: 0.000455 | Q64: 4.5e-05 | R64: 0.003470299 | S64: p__Bacteroidota; c__Bacteroidia; o__; f__; g__ | T64: =AVERAGE('Table S1_MAG quality'!$N64:$R64)
... A69: CAN_5_bin.167 | B69: Ignavibacteria.21 | C69: Bacteroidota | D69: Ignavibacteria | E69: SJA-28 | F69: OLB5 | G69: OLB5 | H69: 63.96 | I69: 2.89 | J69: 3179265 | K69: 66 | L69: 0.42 | M69: 76706 | N69: 2.79e-05 | O69: 2.91e-05 | P69: 3.1e-05 | Q69: 7.57e-05 | R69: 0.000924 | S69: p__Bacteroidota; c__Ignavibacteria; o__; f__; g__ | T69: =AVERAGE('Table S1_MAG quality'!$N69:$R69)
A70: CAN_5_bin.169 | B70: Spirochaetota.1_m | C70: Spirochaetota | D70: GWE2-31-10 | E70: GWE2-31-10 | F70: GWE2-31-10 | H70: 56.96 | I70: 0.67 | J70: 3117418 | K70: 17 | L70: 0.43 | M70: 295341 | N70: 3.23e-05 | O70: 3.84e-05 | P70: 4.13e-05 | Q70: 0.000225 | R70: 0.001146911 | S70: p__Spirochaetota; c__; o__; f__; g__ | T70: =AVERAGE('Table S1_MAG quality'!$N70:$R70)
A71: CAN_5_bin.173 | B71: Bacteroidia.11 | C71: Bacteroidota | D71: Bacteroidia | E71: CAIKAF01 | F71: CAIKAF01 | G71: JAKRSD01 | H71: 98.12 | I71: 0.98 | J71: 3277565 | K71: 67 | L71: 0.43 | M71: 69621 | N71: 9.45e-05 | O71: 0.000232 | P71: 0.000237 | Q71: 9.32e-05 | R71: 0.000852 | S71: p__Bacteroidota; c__Bacteroidia; o__; f__; g__ | T71: =AVERAGE('Table S1_MAG quality'!$N71:$R71)
...

Sheet Table S2a_RPKM per MAG
A1: Table S2a. Abundance of target genes (RPKM) per MAG
A2: K00376 is split into nosZ I and nosZ II columns.
A3: MAGs | B3: iterative ID | C3: RPKM_K00370 | D3: RPKM_K00371 | E3: RPKM_K00374 | F3: RPKM_K02567 | G3: RPKM_K02568 | H3: RPKM_K15864 | I3: RPKM_K00368 | J3: RPKM_K04561 | K3: RPKM_K02305 | L3: RPKM_nosZ I | M3: RPKM_nosZ II | N3: RPKM_K00362 | O3: RPKM_K00363 | P3: RPKM_K03385 | Q3: RPKM_K15876 | R3: RPKM_K00937 | S3: RPKM_K22468 | T3: RPKM_K01514 | U3: RPKM_K02036 | V3: RPKM_K02037 | W3: RPKM_K02038 | X3: RPKM_K02040 | Y3: RPKM_K02035 | Z3: RPKM_K02039 | AA3: RPKM_K07636 | AB3: RPKM_K07657 | AC3: RPKM_K00688 | AD3: RPKM_K00700 | AE3: RPKM_K00703 | AF3: RPKM_K00702 | AG3: RPKM_K01214 | AH3: RPKM_K00626 | AI3: RPKM_K00023 | AJ3: RPKM_K03821 | AK3: RPKM_K00634 | AL3: RPKM_K00925 | AM3: RPKM_K01895 | AN3: RPKM_K01659 | AO3: RPKM_K01720 | AP3: RPKM_K01908 | AQ3: RPKM_K01847 | AR3: RPKM_K01848 | AS3: RPKM_K05973
C4: narG / narZ / nxrA | D4: narH / narY / nxrB | E4: narI / narV / nxrC | F4: napA | G4: napB | H4: nirS | I4: nirK | J4: norB | K4: norC | L4: nosZ_I | M4: nosZ_II | N4: nirB | O4: nirD | P4: nrfA | Q4: nrfH | R4: ppk1 | S4: ppk2 | T4: ppx | U4: pstB | V4: pstC | W4: pstA | X4: pstS | Y4: ABC.PE.S | Z4: phoU | AA4: phoR | AB4: phoB | AC4: glgP | AD4: glgB | AE4: glgA | AF4: cp / E2.4.1.20 | AG4: ISA / treX | AH4: phaA / atoB | AI4: phaB / atoB? | AJ4: phaC | AK4: pta | AL4: ackA | AM4: acs | AN4: prpC | AO4: prpD | AP4: prpE | AQ4: mut | AR4: mcmA / mutA | AS4: pct / acyl-CoA transferase
A5: CAN_1_bin.148 | B5: Dokdonella.5 | C5: 0 | D5: 0 | E5: 0 | F5: 0 | G5: 0 | H5: 0 | I5: 0 | J5: 0 | K5: 0 | L5: 0 | M5: 0 | N5: 0 | O5: 0 | P5: 0 | Q5: 0 | R5: 0.68069999999999997 | S5: 0 | T5: 0 | U5: 2.5897000000000001 | V5: 2.2641 | W5: 2.2715999999999998 | X5: 2.0230999999999999 | Y5: 0 | Z5: 2.7227000000000001 | AA5: 2.8523999999999998 | AB5: 2.7795999999999998 | AC5: 0 | AD5: 0 | AE5: 0 | AF5: 0 | AG5: 0 | AH5: 1.6666000000000001 | AI5: 0 | AJ5: 0 | AK5: 0 | AL5: 0 | AM5: 0 | AN5: 0 | AO5: 0 | AP5: 0 | AQ5: 0 | AR5: 0 | AS5: 0
A6: CAN_1_bin.174 | B6: Gracilibacteria.30 | C6: 0 | D6: 0 | E6: 0 | F6: 0 | G6: 0 | H6: 0 | I6: 0 | J6: 0 | K6: 0 | L6: 0 | M6: 0 | N6: 0 | O6: 0 | P6: 0 | Q6: 0 | R6: 0 | S6: 0 | T6: 0 | U6: 0 | V6: 0 | W6: 0 | X6: 0 | Y6: 0 | Z6: 0 | AA6: 0 | AB6: 0 | AC6: 0 | AD6: 0 | AE6: 0 | AF6: 0 | AG6: 0 | AH6: 0 | AI6: 0 | AJ6: 0 | AK6: 0 | AL6: 0 | AM6: 0 | AN6: 0 | AO6: 0 | AP6: 0 | AQ6: 0 | AR6: 0 | AS6: 0
A7: CAN_1_bin.177 | B7: Pararhodobacter.1_m | C7: 0 | D7: 0 | E7: 0 | F7: 0 | G7: 0 | H7: 0 | I7: 0 | J7: 0 | K7: 0 | L7: 0 | M7: 0 | N7: 0 | O7: 0 | P7: 0 | Q7: 0 | R7: 0 | S7: 0 | T7: 0 | U7: 0 | V7: 0 | W7: 0 | X7: 0 | Y7: 0 | Z7: 0 | AA7: 0 | AB7: 0 | AC7: 0 | AD7: 0 | AE7: 0 | AF7: 0 | AG7: 0 | AH7: 0 | AI7: 0 | AJ7: 0 | AK7: 0 | AL7: 0 | AM7: 0 | AN7: 0 | AO7: 0 | AP7: 0 | AQ7: 0 | AR7: 0 | AS7: 0
A8: CAN_1_bin.180 | B8: Bdellovibrio.13 | C8: 0 | D8: 0 | E8: 0 | F8: 0 | G8: 0 | H8: 0 | I8: 0 | J8: 0 | K8: 0 | L8: 0 | M8: 0 | N8: 0 | O8: 0 | P8: 0 | Q8: 0 | R8: 0 | S8: 0 | T8: 0 | U8: 0 | V8: 0 | W8: 0 | X8: 0 | Y8: 0 | Z8: 0 | AA8: 0 | AB8: 0 | AC8: 0 | AD8: 0 | AE8: 0 | AF8: 0 | AG8: 0 | AH8: 0 | AI8: 0 | AJ8: 0 | AK8: 0 | AL8: 0 | AM8: 0 | AN8: 0 | AO8: 0 | AP8: 0 | AQ8: 0 | AR8: 0 | AS8: 0
A9: CAN_1_bin.195 | B9: Ca_Falkowbacteria.7 | C9: 0 | D9: 0 | E9: 0 | F9: 0 | G9: 0 | H9: 0 | I9: 0 | J9: 0 | K9: 0 | L9: 0 | M9: 0 | N9: 0 | O9: 0 | P9: 0 | Q9: 0 | R9: 0 | S9: 0 | T9: 0 | U9: 0 | V9: 0 | W9: 0 | X9: 0 | Y9: 0 | Z9: 0 | AA9: 0 | AB9: 0 | AC9: 0 | AD9: 0 | AE9: 0 | AF9: 0 | AG9: 0 | AH9: 0 | AI9: 0 | AJ9: 0 | AK9: 0 | AL9: 0 | AM9: 0 | AN9: 0 | AO9: 0 | AP9: 0 | AQ9: 0 | AR9: 0 | AS9: 0
A10: CAN_1_bin.2 | B10: Ignavibacteria.5 | C10: 0 | D10: 0 | E10: 0 | F10: 0 | G10: 0 | H10: 0 | I10: 0 | J10: 0 | K10: 0 | L10: 0 | M10: 0 | N10: 0 | O10: 0 | P10: 0 | Q10: 0 | R10: 0 | S10: 0 | T10: 0 | U10: 0 | V10: 0 | W10: 0 | X10: 0 | Y10: 0 | Z10: 0 | AA10: 0 | AB10: 0 | AC10: 0 | AD10: 0 | AE10: 0 | AF10: 0 | AG10: 0 | AH10: 0 | AI10: 0 | AJ10: 0 | AK10: 0 | AL10: 0 | AM10: 0 | AN10: 0 | AO10: 0 | AP10: 0 | AQ10: 0 | AR10: 0 | AS10: 0
A11: CAN_1_bin.210 | B11: Dokdonella.14 | C11: 0 | D11: 0 | E11: 0 | F11: 0 | G11: 0 | H11: 0 | I11: 0 | J11: 0 | K11: 0 | L11: 0 | M11: 0 | N11: 0 | O11: 0 | P11: 0 | Q11: 0 | R11: 0 | S11: 0 | T11: 0 | U11: 0 | V11: 0 | W11: 0 | X11: 0 | Y11: 0 | Z11: 0 | AA11: 0 | AB11: 0 | AC11: 0 | AD11: 0 | AE11: 0 | AF11: 0 | AG11: 0 | AH11: 0 | AI11: 0 | AJ11: 0 | AK11: 0 | AL11: 0 | AM11: 0 | AN11: 0 | AO11: 0 | AP11: 0 | AQ11: 0 | AR11: 0 | AS11: 0
A12: CAN_1_bin.48 | B12: Paceibacteria.1_m | C12: 0 | D12: 0 | E12: 0 | F12: 0 | G12: 0 | H12: 0 | I12: 0 | J12: 0 | K12: 0 | L12: 0 | M12: 0 | N12: 0 | O12: 0 | P12: 0 | Q12: 0 | R12: 0 | S12: 0 | T12: 0 | U12: 0 | V12: 0 | W12: 0 | X12: 0 | Y12: 0 | Z12: 0 | AA12: 0 | AB12: 0 | AC12: 0 | AD12: 0 | AE12: 0 | AF12: 0 | AG12: 0 | AH12: 0 | AI12: 0 | AJ12: 0 | AK12: 0 | AL12: 0 | AM12: 0 | AN12: 0 | AO12: 0 | AP12: 0 | AQ12: 0 | AR12: 0 | AS12: 0
A13: CAN_1_bin.5 | B13: Micavibrionaceae.1_m | C13: 0 | D13: 0 | E13: 0 | F13: 0 | G13: 0 | H13: 0 | I13: 0 | J13: 0 | K13: 0 | L13: 0 | M13: 0 | N13: 0 | O13: 0 | P13: 0 | Q13: 0 | R13: 0 | S13: 0 | T13: 0 | U13: 0 | V13: 0 | W13: 0 | X13: 0 | Y13: 0 | Z13: 0 | AA13: 0 | AB13: 0 | AC13: 0 | AD13: 0 | AE13: 0 | AF13: 0 | AG13: 0 | AH13: 0 | AI13: 20.061499999999999 | AJ13: 10.999499999999999 | AK13: 0 | AL13: 19.871400000000001 | AM13: 0 | AN13: 0 | AO13: 0 | AP13: 0 | AQ13: 0 | AR13: 0 | AS13: 0
A14: CAN_1_bin.77 | B14: Thermoanaerobaculia.1_m | C14: 0 | D14: 0 | E14: 0 | F14: 0 | G14: 0 | H14: 0 | I14: 0 | J14: 0 | K14: 0 | L14: 0 | M14: 0 | N14: 0 | O14: 0 | P14: 0 | Q14: 0 | R14: 0 | S14: 0 | T14: 0 | U14: 0 | V14: 0 | W14: 0 | X14: 0 | Y14: 0 | Z14: 0 | AA14: 0 | AB14: 0 | AC14: 0 | AD14: 0 | AE14: 0 | AF14: 0 | AG14: 0 | AH14: 0 | AI14: 0 | AJ14: 0 | AK14: 0 | AL14: 0 | AM14: 0 | AN14: 0 | AO14: 0 | AP14: 0 | AQ14: 0 | AR14: 13.2034 | AS14: 0
A15: CAN_1_bin.84 | B15: Phototrophicaceae.1_m | C15: 0 | D15: 0 | E15: 0 | F15: 0 | G15: 0 | H15: 0 | I15: 3.9771999999999998 | J15: 0 | K15: 0 | L15: 0 | M15: 0 | N15: 0 | O15: 0 | P15: 0 | Q15: 0 | R15: 0 | S15: 0 | T15: 0 | U15: 3.0828000000000002 | V15: 8.6744000000000003 | W15: 2.4459 | X15: 0 | Y15: 0 | Z15: 0 | AA15: 0 | AB15: 0 | AC15: 0 | AD15: 0 | AE15: 0 | AF15: 0 | AG15: 0 | AH15: 14.4015 | AI15: 0 | AJ15: 0 | AK15: 0 | AL15: 0 | AM15: 0 | AN15: 0 | AO15: 0 | AP15: 0 | AQ15: 0 | AR15: 0 | AS15: 0
A16: CAN_1_bin.98 | B16: Ca_Accumulibacter.23 | C16: 0 | D16: 0 | E16: 0 | F16: 0 | G16: 0 | H16: 0 | I16: 0 | J16: 0 | K16: 0 | L16: 0 | M16: 0 | N16: 48.147100000000002 | O16: 31.465299999999999 | P16: 0 | Q16: 0 | R16: 0 | S16: 38.790300000000002 | T16: 0 | U16: 0 | V16: 0 | W16: 0 | X16: 45.581800000000001 | Y16: 0 | Z16: 0 | AA16: 0 | AB16: 0 | AC16: 44.936300000000003 | AD16: 0 | AE16: 39.883200000000002 | AF16: 0 | AG16: 0 | AH16: 101.24299999999999 | AI16: 0 | AJ16: 80.185299999999998 | AK16: 0 | AL16: 0 | AM16: 0 | AN16: 0 | AO16: 0 | AP16: 0 | AQ16: 0 | AR16: 0 | AS16: 0
... A280: coasm_bin.93 | B280: Micropepsaceae.1 | C280: 0 | D280: 0 | E280: 0 | F280: 0 | G280: 0 | H280: 0 | I280: 0 | J280: 0 | K280: 0 | L280: 0 | M280: 0 | N280: 0 | O280: 0 | P280: 0 | Q280: 0 | R280: 0.56710000000000005 | S280: 0.3629 | T280: 0 | U280: 0.94330000000000003 | V280: 0.33810000000000001 | W280: 0.75149999999999995 | X280: 0.60899999999999999 | Y280: 3.2753000000000001 | Z280: 0.99970000000000003 | AA280: 0.70730000000000004 | AB280: 1.0471999999999999 | AC280: 0 | AD280: 0 | AE280: 0 | AF280: 0 | AG280: 0 | AH280: 6.2375999999999996 | AI280: 0.74619999999999997 | AJ280: 2.3184999999999998 | AK280: 0 | AL280: 0 | AM280: 0.49330000000000002 | AN280: 0 | AO280: 0 | AP280: 0 | AQ280: 2.1145 | AR280: 0 | AS280: 0.79249999999999998

Sheet Table S2b_RPKM per sample
A1: Table S2b. Abundance of target genes (RPKM) per sample
A2: Use one row per sample. K00376 is split into nosZ I and nosZ II columns.
A3: Sample ID | B3: RPKM_K00370 | C3: RPKM_K00371 | D3: RPKM_K00374 | E3: RPKM_K02567 | F3: RPKM_K02568 | G3: RPKM_K15864 | H3: RPKM_K00368 | I3: RPKM_K04561 | J3: RPKM_K02305 | K3: RPKM_nosZ I | L3: RPKM_nosZ II | M3: RPKM_K00362 | N3: RPKM_K00363 | O3: RPKM_K03385 | P3: RPKM_K15876 | Q3: RPKM_K00937 | R3: RPKM_K22468 | S3: RPKM_K01514 | T3: RPKM_K02036 | U3: RPKM_K02037 | V3: RPKM_K02038 | W3: RPKM_K02040 | X3: RPKM_K02035 | Y3: RPKM_K02039 | Z3: RPKM_K07636 | AA3: RPKM_K07657 | AB3: RPKM_K00688 | AC3: RPKM_K00700 | AD3: RPKM_K00703 | AE3: RPKM_K00702 | AF3: RPKM_K01214 | AG3: RPKM_K00134 | AH3: RPKM_K01596 | AI3: RPKM_K01006 | AJ3: RPKM_K00626 | AK3: RPKM_K00023 | AL3: RPKM_K03821 | AM3: RPKM_K00634 | AN3: RPKM_K00925 | AO3: RPKM_K01895 | AP3: RPKM_K01659 | AQ3: RPKM_K01720 | AR3: RPKM_K01908 | AS3: RPKM_K01847 | AT3: RPKM_K01848 | AU3: RPKM_K05973
B4: narG / narZ / nxrA | C4: narH / narY / nxrB | D4: narI / narV / nxrC | E4: napA | F4: napB | G4: nirS | H4: nirK | I4: norB | J4: norC | K4: nosZ_I | L4: nosZ_II | M4: nirB | N4: nirD | O4: nrfA | P4: nrfH | Q4: ppk1 | R4: ppk2 | S4: ppx | T4: pstB | U4: pstC | V4: pstA | W4: pstS | X4: ABC.PE.S | Y4: phoU | Z4: phoR | AA4: phoB | AB4: glgP | AC4: glgB | AD4: glgA | AE4: cp / E2.4.1.20 | AF4: ISA / treX | AG4: gapA / gap | AH4: pckA | AI4: ppdk | AJ4: phaA / atoB | AK4: phaB / atoB? | AL4: phaC | AM4: pta | AN4: ackA | AO4: acs | AP4: prpC | AQ4: prpD | AR4: prpE | AS4: mut | AT4: mcmA / mutA | AU4: pct / acyl-CoA transferase
A5: CAN_1 | B5: 815.7527 | C5: 1585.3367000000001 | D5: 496.7919 | E5: 164.51990000000001 | F5: 319.35070000000002 | G5: 755.51639999999998 | H5: 272.77969999999999 | I5: 576.94330000000002 | J5: 974.82429999999999 | K5: 71.787000000000006 | L5: 375.20310000000001 | M5: 972.63599999999997 | N5: 729.62379999999996 | O5: 620.67089999999996 | P5: 164.47640000000001 | Q5: 1494.0555999999999 | R5: 564.82240000000002 | S5: 1.1043000000000001 | T5: 1173.3851 | U5: 1060.9703 | V5: 934.00059999999996 | W5: 1815.1513 | X5: 1516.6178 | Y5: 1365.4380000000001 | Z5: 981.09540000000004 | AA5: 1062.0938000000001 | AB5: 1369.1443999999999 | AC5: 1480.5106000000001 | AD5: 587.60699999999997 | AE5: 495.53820000000002 | AF5: 991.42489999999998 | AJ5: 3035.7739000000001 | AK5: 904.45249999999999 | AL5: 2359.1873999999998 | AM5: 596.6019 | AN5: 1419.8732 | AO5: 2493.7791000000002 | AP5: 117.3052 | AQ5: 67.479200000000006 | AR5: 306.67509999999999 | AS5: 2626.3063999999999 | AT5: 446.81229999999999 | AU5: 317.0557
A6: CAN_2 | B6: 815.32650000000001 | C6: 1528.5678 | D6: 501.73239999999998 | E6: 206.96209999999999 | F6: 478.70589999999999 | G6: 749.40660000000003 | H6: 175.31700000000001 | I6: 616.56610000000001 | J6: 1144.6987999999999 | K6: 146.4271 | L6: 243.95150000000001 | M6: 1038.2379000000001 | N6: 879.33640000000003 | O6: 398.23489999999998 | P6: 125.4074 | Q6: 1534.0161000000001 | R6: 521.84460000000001 | S6: 3.0720999999999998 | T6: 1159.3963000000001 | U6: 1021.0732 | V6: 966.3193 | W6: 1772.5300999999999 | X6: 1394.5757000000001 | Y6: 1355.9082000000001 | Z6: 960.74919999999997 | AA6: 1136.8647000000001 | AB6: 1330.4041 | AC6: 1567.0751 | AD6: 574.47580000000005 | AE6: 439.25760000000002 | AF6: 1002.1421 | AJ6: 3261.4528 | AK6: 1248.9799 | AL6: 2502.0572999999999 | AM6: 647.27539999999999 | AN6: 1645.9293 | AO6: 2607.8159999999998 | AP6: 102.45399999999999 | AQ6: 46.346899999999998 | AR6: 343.34449999999998 | AS6: 2633.5043000000001 | AT6: 348.791 | AU6: 379.41919999999999
A7: CAN_3 | B7: 837.71370000000002 | C7: 1555.5350000000001 | D7: 526.41880000000003 | E7: 191.49590000000001 | F7: 465.84269999999998 | G7: 759.81500000000005 | H7: 175.1574 | I7: 637.60670000000005 | J7: 1162.4387999999999 | K7: 137.61259999999999 | L7: 253.6653 | M7: 1029.9123 | N7: 868.62429999999995 | O7: 406.46660000000003 | P7: 124.4907 | Q7: 1567.6628000000001 | R7: 533.00009999999997 | S7: 3.1040000000000001 | T7: 1192.7025000000001 | U7: 1051.9545000000001 | V7: 988.24760000000003 | W7: 1801.4069999999999 | X7: 1482.5708999999999 | Y7: 1350.0344 | Z7: 950.92079999999999 | AA7: 1093.3496 | AB7: 1359.5402999999999 | AC7: 1563.3938000000001 | AD7: 593.95799999999997 | AE7: 441.81259999999997 | AF7: 990.39110000000005 | AJ7: 3175.5852 | AK7: 1203.8779 | AL7: 2450.8454999999999 | AM7: 640.99670000000003 | AN7: 1639.4690000000001 | AO7: 2605.8337999999999 | AP7: 104.8947 | AQ7: 53.085500000000003 | AR7: 332.8922 | AS7: 2623.8542000000002 | AT7: 362.4298 | AU7: 389.53129999999999
A8: CAN_4 | B8: 419.53140000000002 | C8: 698.65480000000002 | D8: 288.53640000000001 | E8: 174.28319999999999 | F8: 274.24110000000002 | G8: 680.18320000000006 | H8: 366.93619999999999 | I8: 542.05399999999997 | J8: 474.5206 | K8: 58.480400000000003 | L8: 527.221 | M8: 657.24 | N8: 718.48519999999996 | O8: 698.73910000000001 | P8: 224.37559999999999 | Q8: 1127.8622 | R8: 1067.6322 | S8: 0 | T8: 1025.6772000000001 | U8: 926.79240000000004 | V8: 747.29949999999997 | W8: 1655.3994 | X8: 1747.9335000000001 | Y8: 1179.4455 | Z8: 989.53639999999996 | AA8: 839.42840000000001 | AB8: 1102.2654 | AC8: 1371.0916999999999 | AD8: 789.15419999999995 | AE8: 362.88229999999999 | AF8: 1070.4784 | AJ8: 2523.3413999999998 | AK8: 647.02530000000002 | AL8: 2055.7446 | AM8: 419.89440000000002 | AN8: 799.38739999999996 | AO8: 1646.5663 | AP8: 165.7756 | AQ8: 157.9417 | AR8: 346.77249999999998 | AS8: 1449.0153 | AT8: 519.12350000000004 | AU8: 306.41910000000001
A9: CAN_5 | B9: 216.8253 | C9: 338.4178 | D9: 184.35659999999999 | E9: 236.15119999999999 | F9: 442.149 | G9: 771.82770000000005 | H9: 349.47910000000002 | I9: 449.3578 | J9: 340.24020000000002 | K9: 47.627699999999997 | L9: 467.59899999999999 | M9: 554.45090000000005 | N9: 686.44159999999999 | O9: 296.52260000000001 | P9: 140.31569999999999 | Q9: 986.25630000000001 | R9: 1088.3153 | S9: 0 | T9: 845.5874 | U9: 670.59469999999999 | V9: 654.88739999999996 | W9: 1273.5044 | X9: 1575.5601999999999 | Y9: 935.80470000000003 | Z9: 985.8048 | AA9: 895.7373 | AB9: 1313.6932999999999 | AC9: 1167.1117999999999 | AD9: 692.44479999999999 | AE9: 277.78769999999997 | AF9: 971.51760000000002 | AJ9: 2162.2053000000001 | AK9: 538.43740000000003 | AL9: 1504.2512999999999 | AM9: 419.96190000000001 | AN9: 566.67340000000002 | AO9: 1348.3562999999999 | AP9: 156.6412 | AQ9: 181.43039999999999 | AR9: 363.94659999999999 | AS9: 1039.6818000000001 | AT9: 468.27679999999998 | AU9: 589.14189999999996

Sheet Table S3_gene copies
A1: Table S3. Gene copy number of target genes per MAG
A2: K00376 is split into nosZ I and nosZ II columns.
A3: MAGs | B3: iterative ID | C3: Taxonomy | D3: copy number_K00370 | E3: copy number_K00371 | F3: copy number_K00374 | G3: copy number_K02567 | H3: copy number_K02568 | I3: copy number_K15864 | J3: copy number_K00368 | K3: copy number_K04561 | L3: copy number_K02305 | M3: copy number_nosZ I | N3: copy number_nosZ II | O3: copy number_K00362 | P3: copy number_K00363 | Q3: copy number_K03385 | R3: copy number_K15876 | S3: copy number_K00937 | T3: copy number_K22468 | U3: copy number_K01514 | V3: copy number_K02036 | W3: copy number_K02037 | X3: copy number_K02038 | Y3: copy number_K02040 | Z3: copy number_K02035 | AA3: copy number_K02039 | AB3: copy number_K07636 | AC3: copy number_K07657 | AD3: copy number_K00688 | AE3: copy number_K00700 | AF3: copy number_K00703 | AG3: copy number_K00702 | AH3: copy number_K01214 | AI3: copy number_K00134 | AJ3: copy number_K01596 | AK3: copy number_K01006 | AL3: copy number_K00626 | AM3: copy number_K00023 | AN3: copy number_K03821 | AO3: copy number_K00634 | AP3: copy number_K00925 | AQ3: copy number_K01895 | AR3: copy number_K01659 | AS3: copy number_K01720 | AT3: copy number_K01908 | AU3: copy number_K01847 | AV3: copy number_K01848 | AW3: copy number_K05973
D4: narG / narZ / nxrA | E4: narH / narY / nxrB | F4: narI / narV / nxrC | G4: napA | H4: napB | I4: nirS | J4: nirK | K4: norB | L4: norC | M4: nosZ_I | N4: nosZ_II | O4: nirB | P4: nirD | Q4: nrfA | R4: nrfH | S4: ppk1 | T4: ppk2 | U4: ppx | V4: pstB | W4: pstC | X4: pstA | Y4: pstS | Z4: ABC.PE.S | AA4: phoU | AB4: phoR | AC4: phoB | AD4: glgP | AE4: glgB | AF4: glgA | AG4: cp / E2.4.1.20 | AH4: ISA / treX | AI4: gapA / gap | AJ4: pckA | AK4: ppdk | AL4: phaA / atoB | AM4: phaB / atoB? | AN4: phaC | AO4: pta | AP4: ackA | AQ4: acs | AR4: prpC | AS4: prpD | AT4: prpE | AU4: mut | AV4: mcmA / mutA | AW4: pct / acyl-CoA transferase
A5: CAN_1_bin.148 | B5: Dokdonella.5 | C5: =_xlfn.TEXTJOIN(";", TRUE,'Table S1_MAG quality'!C4:G4) | D5: 0 | E5: 0 | F5: 0 | G5: 0 | H5: 0 | I5: 0 | J5: 0 | K5: 0 | L5: 0 | M5: 0 | N5: 0 | O5: 0 | P5: 0 | Q5: 0 | R5: 0 | S5: 1 | T5: 0 | U5: 0 | V5: 1 | W5: 1 | X5: 1 | Y5: 1 | Z5: 0 | AA5: 1 | AB5: 1 | AC5: 1 | AD5: 0 | AE5: 0 | AF5: 0 | AG5: 0 | AH5: 0 | AI5: 1 | AJ5: 1 | AK5: 0 | AL5: 1 | AM5: 0 | AN5: 0 | AO5: 0 | AP5: 0 | AQ5: 0 | AR5: 0 | AS5: 0 | AT5: 0 | AU5: 0 | AV5: 0 | AW5: 0
A6: CAN_1_bin.174 | B6: Gracilibacteria.30 | C6: =_xlfn.TEXTJOIN(";", TRUE,'Table S1_MAG quality'!C5:G5) | D6: 0 | E6: 0 | F6: 0 | G6: 0 | H6: 0 | I6: 0 | J6: 0 | K6: 0 | L6: 0 | M6: 0 | N6: 0 | O6: 0 | P6: 0 | Q6: 0 | R6: 0 | S6: 0 | T6: 0 | U6: 0 | V6: 0 | W6: 0 | X6: 0 | Y6: 0 | Z6: 0 | AA6: 0 | AB6: 0 | AC6: 0 | AD6: 0 | AE6: 0 | AF6: 0 | AG6: 0 | AH6: 0 | AI6: 0 | AJ6: 0 | AK6: 0 | AL6: 0 | AM6: 0 | AN6: 0 | AO6: 0 | AP6: 0 | AQ6: 0 | AR6: 0 | AS6: 0 | AT6: 0 | AU6: 0 | AV6: 0 | AW6: 0
A7: CAN_1_bin.177 | B7: Pararhodobacter.1_m | C7: =_xlfn.TEXTJOIN(";", TRUE,'Table S1_MAG quality'!C6:G6) | D7: 0 | E7: 0 | F7: 0 | G7: 0 | H7: 0 | I7: 0 | J7: 0 | K7: 0 | L7: 0 | M7: 1 | N7: 0 | O7: 0 | P7: 0 | Q7: 0 | R7: 0 | S7: 0 | T7: 0 | U7: 0 | V7: 0 | W7: 0 | X7: 0 | Y7: 0 | Z7: 0 | AA7: 0 | AB7: 0 | AC7: 0 | AD7: 0 | AE7: 0 | AF7: 0 | AG7: 0 | AH7: 0 | AI7: 2 | AJ7: 0 | AK7: 1 | AL7: 0 | AM7: 0 | AN7: 0 | AO7: 0 | AP7: 0 | AQ7: 0 | AR7: 0 | AS7: 0 | AT7: 0 | AU7: 0 | AV7: 0 | AW7: 0
A8: CAN_1_bin.180 | B8: Bdellovibrio.13 | C8: =_xlfn.TEXTJOIN(";", TRUE,'Table S1_MAG quality'!C7:G7) | D8: 0 | E8: 0 | F8: 0 | G8: 0 | H8: 0 | I8: 0 | J8: 0 | K8: 0 | L8: 0 | M8: 0 | N8: 0 | O8: 0 | P8: 0 | Q8: 0 | R8: 0 | S8: 0 | T8: 0 | U8: 0 | V8: 0 | W8: 0 | X8: 0 | Y8: 0 | Z8: 0 | AA8: 0 | AB8: 0 | AC8: 0 | AD8: 0 | AE8: 0 | AF8: 0 | AG8: 0 | AH8: 0 | AI8: 1 | AJ8: 1 | AK8: 1 | AL8: 0 | AM8: 0 | AN8: 0 | AO8: 0 | AP8: 0 | AQ8: 0 | AR8: 0 | AS8: 0 | AT8: 0 | AU8: 0 | AV8: 0 | AW8: 0
A9: CAN_1_bin.195 | B9: Ca_Falkowbacteria.7 | C9: =_xlfn.TEXTJOIN(";", TRUE,'Table S1_MAG quality'!C8:G8) | D9: 0 | E9: 0 | F9: 0 | G9: 0 | H9: 0 | I9: 0 | J9: 0 | K9: 0 | L9: 0 | M9: 0 | N9: 0 | O9: 0 | P9: 0 | Q9: 0 | R9: 0 | S9: 0 | T9: 0 | U9: 0 | V9: 0 | W9: 0 | X9: 0 | Y9: 0 | Z9: 0 | AA9: 0 | AB9: 0 | AC9: 0 | AD9: 0 | AE9: 0 | AF9: 0 | AG9: 0 | AH9: 0 | AI9: 1 | AJ9: 0 | AK9: 0 | AL9: 0 | AM9: 0 | AN9: 0 | AO9: 0 | AP9: 0 | AQ9: 0 | AR9: 0 | AS9: 0 | AT9: 0 | AU9: 0 | AV9: 0 | AW9: 0
A10: CAN_1_bin.2 | B10: Ignavibacteria.5 | C10: =_xlfn.TEXTJOIN(";", TRUE,'Table S1_MAG quality'!C9:G9) | D10: 0 | E10: 0 | F10: 0 | G10: 0 | H10: 0 | I10: 0 | J10: 0 | K10: 0 | L10: 0 | M10: 0 | N10: 0 | O10: 0 | P10: 0 | Q10: 0 | R10: 0 | S10: 0 | T10: 0 | U10: 0 | V10: 0 | W10: 0 | X10: 0 | Y10: 0 | Z10: 0 | AA10: 0 | AB10: 0 | AC10: 0 | AD10: 0 | AE10: 0 | AF10: 0 | AG10: 0 | AH10: 0 | AI10: 1 | AJ10: 1 | AK10: 1 | AL10: 0 | AM10: 0 | AN10: 0 | AO10: 0 | AP10: 0 | AQ10: 0 | AR10: 0 | AS10: 0 | AT10: 0 | AU10: 0 | AV10: 0 | AW10: 0
A11: CAN_1_bin.210 | B11: Dokdonella.14 | C11: =_xlfn.TEXTJOIN(";", TRUE,'Table S1_MAG quality'!C10:G10) | D11: 0 | E11: 0 | F11: 0 | G11: 0 | H11: 0 | I11: 0 | J11: 0 | K11: 0 | L11: 0 | M11: 0 | N11: 0 | O11: 0 | P11: 0 | Q11: 0 | R11: 0 | S11: 0 | T11: 0 | U11: 0 | V11: 0 | W11: 0 | X11: 0 | Y11: 0 | Z11: 0 | AA11: 0 | AB11: 0 | AC11: 0 | AD11: 0 | AE11: 0 | AF11: 0 | AG11: 0 | AH11: 0 | AI11: 1 | AJ11: 1 | AK11: 0 | AL11: 0 | AM11: 0 | AN11: 0 | AO11: 0 | AP11: 0 | AQ11: 0 | AR11: 0 | AS11: 0 | AT11: 0 | AU11: 0 | AV11: 0 | AW11: 0
A12: CAN_1_bin.48 | B12: Paceibacteria.1_m | C12: =_xlfn.TEXTJOIN(";", TRUE,'Table S1_MAG quality'!C11:G11) | D12: 0 | E12: 0 | F12: 0 | G12: 0 | H12: 0 | I12: 0 | J12: 0 | K12: 0 | L12: 0 | M12: 0 | N12: 0 | O12: 0 | P12: 0 | Q12: 0 | R12: 0 | S12: 0 | T12: 0 | U12: 0 | V12: 0 | W12: 0 | X12: 0 | Y12: 0 | Z12: 0 | AA12: 0 | AB12: 0 | AC12: 0 | AD12: 0 | AE12: 0 | AF12: 0 | AG12: 0 | AH12: 0 | AI12: 0 | AJ12: 0 | AK12: 0 | AL12: 0 | AM12: 0 | AN12: 0 | AO12: 0 | AP12: 0 | AQ12: 0 | AR12: 0 | AS12: 0 | AT12: 0 | AU12: 0 | AV12: 0 | AW12: 0
A13: CAN_1_bin.5 | B13: Micavibrionaceae.1_m | C13: =_xlfn.TEXTJOIN(";", TRUE,'Table S1_MAG quality'!C12:G12) | D13: 0 | E13: 0 | F13: 0 | G13: 0 | H13: 0 | I13: 0 | J13: 0 | K13: 0 | L13: 0 | M13: 0 | N13: 0 | O13: 0 | P13: 0 | Q13: 0 | R13: 0 | S13: 0 | T13: 0 | U13: 0 | V13: 0 | W13: 0 | X13: 0 | Y13: 0 | Z13: 0 | AA13: 0 | AB13: 0 | AC13: 0 | AD13: 0 | AE13: 0 | AF13: 0 | AG13: 0 | AH13: 0 | AI13: 1 | AJ13: 0 | AK13: 1 | AL13: 0 | AM13: 1 | AN13: 1 | AO13: 0 | AP13: 1 | AQ13: 0 | AR13: 0 | AS13: 0 | AT13: 0 | AU13: 0 | AV13: 0 | AW13: 0
A14: CAN_1_bin.77 | B14: Thermoanaerobaculia.1_m | C14: =_xlfn.TEXTJOIN(";", TRUE,'Table S1_MAG quality'!C13:G13) | D14: 0 | E14: 0 | F14: 0 | G14: 0 | H14: 0 | I14: 0 | J14: 0 | K14: 0 | L14: 0 | M14: 0 | N14: 1 | O14: 0 | P14: 0 | Q14: 0 | R14: 0 | S14: 0 | T14: 0 | U14: 0 | V14: 0 | W14: 0 | X14: 0 | Y14: 0 | Z14: 0 | AA14: 0 | AB14: 0 | AC14: 0 | AD14: 0 | AE14: 0 | AF14: 0 | AG14: 0 | AH14: 0 | AI14: 1 | AJ14: 1 | AK14: 1 | AL14: 0 | AM14: 0 | AN14: 0 | AO14: 0 | AP14: 0 | AQ14: 0 | AR14: 0 | AS14: 0 | AT14: 0 | AU14: 0 | AV14: 1 | AW14: 0
A15: CAN_1_bin.84 | B15: Phototrophicaceae.1_m | C15: =_xlfn.TEXTJOIN(";", TRUE,'Table S1_MAG quality'!C14:G14) | D15: 0 | E15: 0 | F15: 0 | G15: 0 | H15: 0 | I15: 0 | J15: 1 | K15: 0 | L15: 0 | M15: 0 | N15: 0 | O15: 0 | P15: 0 | Q15: 0 | R15: 0 | S15: 0 | T15: 0 | U15: 0 | V15: 1 | W15: 1 | X15: 1 | Y15: 0 | Z15: 0 | AA15: 0 | AB15: 0 | AC15: 0 | AD15: 0 | AE15: 0 | AF15: 0 | AG15: 0 | AH15: 0 | AI15: 1 | AJ15: 1 | AK15: 1 | AL15: 2 | AM15: 0 | AN15: 0 | AO15: 0 | AP15: 0 | AQ15: 0 | AR15: 0 | AS15: 0 | AT15: 0 | AU15: 0 | AV15: 0 | AW15: 0
A16: CAN_1_bin.98 | B16: Ca_Accumulibacter.23 | C16: =_xlfn.TEXTJOIN(";", TRUE,'Table S1_MAG quality'!C15:G15) | D16: 0 | E16: 0 | F16: 0 | G16: 0 | H16: 0 | I16: 0 | J16: 0 | K16: 0 | L16: 0 | M16: 0 | N16: 1 | O16: 1 | P16: 1 | Q16: 0 | R16: 0 | S16: 0 | T16: 1 | U16: 0 | V16: 0 | W16: 0 | X16: 0 | Y16: 1 | Z16: 0 | AA16: 0 | AB16: 0 | AC16: 0 | AD16: 1 | AE16: 0 | AF16: 1 | AG16: 0 | AH16: 0 | AI16: 1 | AJ16: 1 | AK16: 1 | AL16: 2 | AM16: 0 | AN16: 2 | AO16: 0 | AP16: 0 | AQ16: 0 | AR16: 0 | AS16: 0 | AT16: 0 | AU16: 0 | AV16: 0 | AW16: 0
... A280: coasm_bin.93 | B280: Micropepsaceae.1 | C280: =_xlfn.TEXTJOIN(";", TRUE,'Table S1_MAG quality'!C279:G279) | D280: 0 | E280: 0 | F280: 0 | G280: 0 | H280: 0 | I280: 0 | J280: 0 | K280: 0 | L280: 0 | M280: 0 | N280: 0 | O280: 0 | P280: 0 | Q280: 0 | R280: 0 | S280: 1 | T280: 1 | U280: 0 | V280: 1 | W280: 1 | X280: 2 | Y280: 1 | Z280: 6 | AA280: 1 | AB280: 1 | AC280: 1 | AD280: 0 | AE280: 0 | AF280: 0 | AG280: 0 | AH280: 0 | AI280: 1 | AJ280: 0 | AK280: 1 | AL280: 9 | AM280: 1 | AN280: 3 | AO280: 0 | AP280: 0 | AQ280: 1 | AR280: 0 | AS280: 0 | AT280: 0 | AU280: 1 | AV280: 0 | AW280: 1
C281: =_xlfn.TEXTJOIN(";", TRUE,'Table S1_MAG quality'!C281:G281)
C282: =_xlfn.TEXTJOIN(";", TRUE,'Table S1_MAG quality'!C281:G281)
C283: =_xlfn.TEXTJOIN(";", TRUE,'Table S1_MAG quality'!C282:G282)

Sheet Table S4_nosZ_genecopy_type
A1: Table S4. Mags with NosZ genes, type and copy number
A2: Rerference tree
A3: MAG | B3: MAG iteration ID | C3: genus | D3: nosZ_copies | E3: cladeI | F3: cladeII | G3: cladeIII | H3: clade_call | I3: best_hmm_score
A4: CAN_1_bin.177 | B4: midas_g_155.3_ma | C4: Pararhodobacter | D4: 1 | E4: 1 | F4: 0 | G4: 0 | H4: I | I4: 755.8
A5: CAN_1_bin.77 | B5: UBA5066.1_m | C5: UBA5066 | D5: 1 | E5: 0 | F5: 1 | G5: 0 | H5: II | I5: 716.6
A6: CAN_1_bin.98 | B6: Ca_Accumulibacter.23_ma | C6: Accumulibacter | D6: 1 | E6: 0 | F6: 1 | G6: 0 | H6: II | I6: 714.7
A7: CAN_2_bin.173 | B7: JACDQM01.1_m | C7: JACDQM01 | D7: 1 | E7: 1 | F7: 0 | G7: 0 | H7: I | I7: 515.2
A8: CAN_2_bin.176 | B8: UBA5066.2_m | C8: UBA5066 | D8: 1 | E8: 0 | F8: 1 | G8: 0 | H8: II | I8: 725.8
A9: CAN_2_bin.23 | B9: Zoogloea.11_ma | C9: Zoogloea | D9: 1 | E9: 1 | F9: 0 | G9: 0 | H9: I | I9: 747.4
A10: CAN_2_bin.6 | B10: Denitratisoma.2_ma | C10: Desulfobacillus | D10: 1 | E10: 0 | F10: 1 | G10: 0 | H10: II | I10: 727
A11: CAN_2_bin.66 | B11: JACTMZ01.1_m | C11: JACTMZ01 | D11: 1 | E11: 0 | F11: 1 | G11: 0 | H11: II | I11: 691.3
A12: CAN_3_bin.10 | B12: Rhodobacter.13_ma | C12: JAAKGP01 | D12: 1 | E12: 1 | F12: 0 | G12: 0 | H12: I | I12: 745.8
A13: CAN_3_bin.203 | B13: JAEULV01.1_m | C13: JAEULV01 | D13: 1 | E13: 0 | F13: 1 | G13: 0 | H13: II | I13: 701
A14: CAN_3_bin.205 | B14: Niabella.2_ma | C14: Niabella | D14: 1 | E14: 0 | F14: 1 | G14: 0 | H14: II | I14: 720
A15: CAN_3_bin.208 | B15: Sulfuritalea.5_ma | C15: Azospira_A | D15: 1 | E15: 0 | F15: 1 | G15: 0 | H15: II | I15: 724.4
... A125: coasm_bin.61 | B125: midas_g_9628.1_ma | C125: UBA1930 | D125: 1 | E125: 0 | F125: 1 | G125: 0 | H125: II | I125: 721

Sheet Table S5 _ppk_ACC
A1: Table S4. Mags with NosZ genes, type and copy number
A2: Rerference tree
A3: MAG | B3: MAG iteration ID | C3: ppk1_type | D3: proposed_species | E3: SH-aLRT/UFBoot | F3: top_pid | G3: nearest_reference | H3: note
A4: CAN_1_bin.98 | C4: Type I (unclassified) | E4: / | F4: 87.7% (IE) | G4: Candidatus Accumulibacter sp. UBA11064 | H4: Type I, divergent/novel (max id ~88%, no established clade)
A5: CAN_4_bin.225 | C5: no ppk1 recovered | H5: Accumulibacter, ~92% size but 99 contigs (N50 85 kb); no ppk1 ORF assembled - gene likely split across a contig break (KO K00937=1 = sub-HMM fragment, not a full gene)
A6: CAN_4_bin.64 | C6: Type I (unclassified) | E6: 100/100 | F6: 99.1% (un) | G6: Candidatus Accumulibacter sp. UBA11064 | H6: Type I, unclassified (≈UBA11064, 99% id; ~88% to named clades)
A7: coasm_bin.185 | C7: IA | D7: Ca. Accumulibacter regalis | E7: 99.5/100 | F7: 100.0% (IA) | G7: Candidatus Accumulibacter phosphatis CANDO_1; Candidatus Accumulibacter phosphatis UW3; UCB HP1-ppk2 -02 | H7: clade IA
A8: coasm_bin.250 | C8: IC | D8: Ca. Accumulibacter delftensis | E8: 100/100 | F8: 99.8% (IC) | G8: Ca. A. delftensis; Inoc_ppk1_020 | H8: clade IC (delftensis vs meliphilus: closest delftensis)
A9: coasm_bin.347 | C9: IIA | D9: Ca. Accumulibacter phosphatis | E9: 81.9/99 | F9: 99.4% (IIA) | G9: Candidatus Accumulibacter phosphatis UW1; Candidatus Accumulibacter phosphatis UW9-POB; Candidatus Accumulibacter phosphatis UW5 | H9: clade IIA (phosphatis lineage, UW1 type strain)
A10: coasm_bin.476 | C10: no ppk1 recovered | H10: Accumulibacter, ~55% complete (2.2 Mb, 4 contigs); ppk1 not recovered in the assembly

Sheet KO_order_mapping
A1: module | B1: submodule | C1: KO | D1: gene | E1: enzyme_note
A2: Denitrification / N-cycle | B2: NO3_to_NO2 | C2: K00370 | D2: narG/narZ/nxrA | E2: nitrate reductase / nitrite oxidoreductase alpha subunit
A3: Denitrification / N-cycle | B3: NO3_to_NO2 | C3: K00371 | D3: narH/narY/nxrB | E3: nitrate reductase / nitrite oxidoreductase beta subunit
A4: Denitrification / N-cycle | B4: NO3_to_NO2 | C4: K00374 | D4: narI/narV | E4: nitrate reductase gamma subunit
A5: Denitrification / N-cycle | B5: NO3_to_NO2 | C5: K02567 | D5: napA | E5: periplasmic nitrate reductase large subunit
A6: Denitrification / N-cycle | B6: NO3_to_NO2 | C6: K02568 | D6: napB | E6: periplasmic nitrate reductase small subunit
A7: Denitrification / N-cycle | B7: NO2_to_NO | C7: K15864 | D7: nirS | E7: cytochrome cd1 nitrite reductase
A8: Denitrification / N-cycle | B8: NO2_to_NO | C8: K00368 | D8: nirK | E8: copper-containing nitrite reductase
A9: Denitrification / N-cycle | B9: NO_to_N2O | C9: K04561 | D9: norB | E9: nitric oxide reductase subunit B
A10: Denitrification / N-cycle | B10: NO_to_N2O | C10: K02305 | D10: norC | E10: nitric oxide reductase subunit C
A11: Denitrification / N-cycle | B11: N2O_to_N2 | C11: nosZ I | D11: nosZ clade I | E11: nitrous oxide reductase clade I
A12: Denitrification / N-cycle | B12: N2O_to_N2 | C12: nosZ II | D12: nosZ clade II | E12: nitrous oxide reductase clade II
... A47: Carbon / PHA / VFA | B47: VFA_activation | C47: K05973 | D47: pct/acyl-CoA transferase | E47: propionate/acyl-CoA transferase; verify

Sheet Table S6_ANI
A1: MAG bin name | B1: MAG iteration ID | C1: GTDB taxonomy | D1: Phylum | E1: Class | F1: Order | G1: Family | H1: Genus | I1: Species | J1: Closest reference genome name | K1: Closest reference accession | L1: Reference database | M1: ANI to closest reference (%) | N1: Alignment fraction / AF | O1: Query coverage (%) | P1: Reference coverage (%) | Q1: Species-level call | R1: Novelty interpretation | S1: Representative retained in Table 2? (Y/N) | T1: Notes
A2: CAN_1_bin.148 | B2: Dokdonella.5 | C2: d__Bacteria;p__Pseudomonadota;c__Gammaproteobacteria;o__Xanthomonadales;f__Rhodanobacteraceae;g__Dokdonella;s__ | D2: Pseudomonadota | E2: Gammaproteobacteria | F2: Xanthomonadales | G2: Rhodanobacteraceae | H2: Dokdonella | L2: GTDB R220 (GTDB-Tk v2.7.2, classify_wf) | Q2: Unresolved by ANI (GTDB species novel; s__ unassigned) | R2: No close ANI hit and GTDB assigns no species (novel at species level; GTDB-resolved to genus); evaluate exact ANI/AF (skani vs GTDB reps) or AAI/phylogeny. | T2: GTDB-Tk classification_method: taxonomic classification fully defined by topology. GTDB-Tk note: classification based on placement in class-level tree.
A3: CAN_1_bin.174 | B3: Gracilibacteria.30 | C3: d__Bacteria;p__Patescibacteria;c__JAEDAM01;o__BD1-5;f__UBA2023;g__UBA5532;s__UBA5532 sp002426885 | D3: Patescibacteria | E3: JAEDAM01 | F3: BD1-5 | G3: UBA2023 | H3: UBA5532 | I3: UBA5532 sp002426885 | J3: UBA5532 sp002426885 | K3: GCA_002426885.1 | L3: GTDB R220 (GTDB-Tk v2.7.2, classify_wf) | M3: 95.25 | N3: 0.836 | Q3: Same species cluster | R3: Same species-level cluster as closest reference. | T3: Distinct genome within GTDB species s__UBA5532 sp002426885; co-member(s): CAN_5_bin.90. Separate dRep 95% representatives (same GTDB species != same dRep cluster); not a dereplication error. GTDB-Tk classification_method: ani_screen. GTDB-Tk note: classification based on ANI only.
A4: CAN_1_bin.177 | B4: Pararhodobacter.1_m | C4: d__Bacteria;p__Pseudomonadota;c__Alphaproteobacteria;o__Rhodobacterales;f__Rhodobacteraceae;g__Pararhodobacter;s__ | D4: Pseudomonadota | E4: Alphaproteobacteria | F4: Rhodobacterales | G4: Rhodobacteraceae | H4: Pararhodobacter | L4: GTDB R220 (GTDB-Tk v2.7.2, classify_wf) | Q4: Unresolved by ANI (GTDB species novel; s__ unassigned) | R4: No close ANI hit and GTDB assigns no species (novel at species level; GTDB-resolved to genus); evaluate exact ANI/AF (skani vs GTDB reps) or AAI/phylogeny. | T4: GTDB-Tk classification_method: taxonomic classification fully defined by topology. GTDB-Tk note: classification based on placement in class-level tree.
A5: CAN_1_bin.180 | B5: Bdellovibrio.13 | C5: d__Bacteria;p__Bdellovibrionota;c__Bdellovibrionia;o__Bdellovibrionales;f__Bdellovibrionaceae;g__UBA2316;s__ | D5: Bdellovibrionota | E5: Bdellovibrionia | F5: Bdellovibrionales | G5: Bdellovibrionaceae | H5: UBA2316 | L5: GTDB R220 (GTDB-Tk v2.7.2, classify_wf) | Q5: Unresolved by ANI (GTDB species novel; s__ unassigned) | R5: No close ANI hit and GTDB assigns no species (novel at species level; GTDB-resolved to genus); evaluate exact ANI/AF (skani vs GTDB reps) or AAI/phylogeny. | T5: GTDB-Tk classification_method: taxonomic classification fully defined by topology. GTDB-Tk note: classification based on placement in class-level tree.
A6: CAN_1_bin.195 | B6: Ca_Falkowbacteria.7 | C6: d__Bacteria;p__Patescibacteria;c__ABY1;o__BM507;f__UBA917;g__UBA919;s__ | D6: Patescibacteria | E6: ABY1 | F6: BM507 | G6: UBA917 | H6: UBA919 | L6: GTDB R220 (GTDB-Tk v2.7.2, classify_wf) | Q6: Unresolved by ANI (GTDB species novel; s__ unassigned) | R6: No close ANI hit and GTDB assigns no species (novel at species level; GTDB-resolved to genus); evaluate exact ANI/AF (skani vs GTDB reps) or AAI/phylogeny. | T6: GTDB-Tk classification_method: taxonomic classification fully defined by topology. GTDB-Tk note: classification based on placement in class-level tree.
A7: CAN_1_bin.2 | B7: Ignavibacteria.5 | C7: d__Bacteria;p__Bacteroidota;c__Ignavibacteria;o__SJA-28;f__B-1AR;g__;s__ | D7: Bacteroidota | E7: Ignavibacteria | F7: SJA-28 | G7: B-1AR | L7: GTDB R220 (GTDB-Tk v2.7.2, classify_wf) | Q7: Unresolved by ANI (GTDB species novel; s__ unassigned) | R7: No close ANI hit and GTDB assigns no species (novel at species level; GTDB-resolved to family); evaluate exact ANI/AF (skani vs GTDB reps) or AAI/phylogeny. | T7: GTDB-Tk classification_method: taxonomic novelty determined using RED. GTDB-Tk note: classification based on placement in class-level tree.
A8: CAN_1_bin.210 | B8: Dokdonella.14 | C8: d__Bacteria;p__Pseudomonadota;c__Gammaproteobacteria;o__Xanthomonadales;f__Rhodanobacteraceae;g__Dokdonella;s__ | D8: Pseudomonadota | E8: Gammaproteobacteria | F8: Xanthomonadales | G8: Rhodanobacteraceae | H8: Dokdonella | L8: GTDB R220 (GTDB-Tk v2.7.2, classify_wf) | Q8: Unresolved by ANI (GTDB species novel; s__ unassigned) | R8: No close ANI hit and GTDB assigns no species (novel at species level; GTDB-resolved to genus); evaluate exact ANI/AF (skani vs GTDB reps) or AAI/phylogeny. | T8: GTDB-Tk classification_method: taxonomic classification fully defined by topology. GTDB-Tk note: classification based on placement in class-level tree.
A9: CAN_1_bin.48 | B9: Paceibacteria.1_m | C9: d__Bacteria;p__Patescibacteria;c__Paceibacteria;o__UBA6257;f__GWB1-50-10;g__;s__ | D9: Patescibacteria | E9: Paceibacteria | F9: UBA6257 | G9: GWB1-50-10 | L9: GTDB R220 (GTDB-Tk v2.7.2, classify_wf) | Q9: Unresolved by ANI (GTDB species novel; s__ unassigned) | R9: No close ANI hit and GTDB assigns no species (novel at species level; GTDB-resolved to family); evaluate exact ANI/AF (skani vs GTDB reps) or AAI/phylogeny. | T9: GTDB-Tk classification_method: taxonomic classification fully defined by topology. GTDB-Tk note: classification based on placement in class-level tree.
A10: CAN_1_bin.5 | B10: Micavibrionaceae.1_m | C10: d__Bacteria;p__Pseudomonadota;c__Alphaproteobacteria;o__Micavibrionales;f__Micavibrionaceae;g__UBA1573;s__UBA1573 sp002425415 | D10: Pseudomonadota | E10: Alphaproteobacteria | F10: Micavibrionales | G10: Micavibrionaceae | H10: UBA1573 | I10: UBA1573 sp002425415 | J10: UBA1573 sp002425415 | K10: GCA_002425415.1 | L10: GTDB R220 (GTDB-Tk v2.7.2, classify_wf) | M10: 99.08 | N10: 0.883 | Q10: Same species cluster | R10: Same species-level cluster as closest reference. | T10: GTDB-Tk classification_method: ani_screen. GTDB-Tk note: classification based on ANI only.
A11: CAN_1_bin.77 | B11: Thermoanaerobaculia.1_m | C11: d__Bacteria;p__Acidobacteriota;c__Thermoanaerobaculia;o__UBA5066;f__UBA5066;g__UBA5066;s__ | D11: Acidobacteriota | E11: Thermoanaerobaculia | F11: UBA5066 | G11: UBA5066 | H11: UBA5066 | L11: GTDB R220 (GTDB-Tk v2.7.2, classify_wf) | Q11: Unresolved by ANI (GTDB species novel; s__ unassigned) | R11: No close ANI hit and GTDB assigns no species (novel at species level; GTDB-resolved to genus); evaluate exact ANI/AF (skani vs GTDB reps) or AAI/phylogeny. | T11: GTDB-Tk classification_method: taxonomic classification fully defined by topology. GTDB-Tk note: classification based on placement in class-level tree.
A12: CAN_1_bin.84 | B12: Phototrophicaceae.1_m | C12: d__Bacteria;p__Chloroflexota;c__Anaerolineae;o__Aggregatilineales;f__Phototrophicaceae;g__CFX2;s__CFX2 sp017303775 | D12: Chloroflexota | E12: Anaerolineae | F12: Aggregatilineales | G12: Phototrophicaceae | H12: CFX2 | I12: CFX2 sp017303775 | J12: CFX2 sp017303775 | K12: GCA_017303775.1 | L12: GTDB R220 (GTDB-Tk v2.7.2, classify_wf) | M12: 98.81 | N12: 0.953 | Q12: Same species cluster | R12: Same species-level cluster as closest reference. | T12: GTDB-Tk classification_method: ani_screen. GTDB-Tk note: classification based on ANI only.
A13: CAN_1_bin.98 | B13: Ca_Accumulibacter.23 | C13: d__Bacteria;p__Pseudomonadota;c__Gammaproteobacteria;o__Burkholderiales;f__Rhodocyclaceae;g__Accumulibacter;s__Accumulibacter sp014879755 | D13: Pseudomonadota | E13: Gammaproteobacteria | F13: Burkholderiales | G13: Rhodocyclaceae | H13: Accumulibacter | I13: Accumulibacter sp014879755 | J13: Accumulibacter sp014879755 | K13: GCF_024235695.1 | L13: GTDB R220 (GTDB-Tk v2.7.2, classify_wf) | M13: 99.48 | N13: 0.963 | Q13: Same species cluster | R13: Same species-level cluster as closest reference. | T13: GTDB-Tk classification_method: ani_screen. GTDB-Tk note: classification based on ANI only.
A14: CAN_2_bin.125 | B14: Pseudoxanthomonas_A.1_m | C14: d__Bacteria;p__Pseudomonadota;c__Gammaproteobacteria;o__Xanthomonadales;f__Xanthomonadaceae;g__Pseudoxanthomonas_A;s__Pseudoxanthomonas_A mexicana | D14: Pseudomonadota | E14: Gammaproteobacteria | F14: Xanthomonadales | G14: Xanthomonadaceae | H14: Pseudoxanthomonas_A | I14: Pseudoxanthomonas_A mexicana | J14: Pseudoxanthomonas_A mexicana | K14: GCF_010093385.1 | L14: GTDB R220 (GTDB-Tk v2.7.2, classify_wf) | M14: 97.15 | N14: 0.867 | Q14: Same species cluster | R14: Same species-level cluster as closest reference. | T14: GTDB-Tk classification_method: ani_screen. GTDB-Tk note: classification based on ANI only.
A15: CAN_2_bin.151 | B15: Brevundimonas.4 | C15: d__Bacteria;p__Pseudomonadota;c__Alphaproteobacteria;o__Caulobacterales;f__Caulobacteraceae;g__Brevundimonas;s__ | D15: Pseudomonadota | E15: Alphaproteobacteria | F15: Caulobacterales | G15: Caulobacteraceae | H15: Brevundimonas | L15: GTDB R220 (GTDB-Tk v2.7.2, classify_wf) | Q15: Unresolved by ANI (GTDB species novel; s__ unassigned) | R15: No close ANI hit and GTDB assigns no species (novel at species level; GTDB-resolved to genus); evaluate exact ANI/AF (skani vs GTDB reps) or AAI/phylogeny. | T15: GTDB-Tk classification_method: taxonomic classification fully defined by topology. GTDB-Tk note: classification based on placement in class-level tree.
A16: CAN_2_bin.159 | B16: Pseudoxanthomonas.23 | C16: d__Bacteria;p__Pseudomonadota;c__Gammaproteobacteria;o__Xanthomonadales;f__Xanthomonadaceae;g__Pseudoxanthomonas;s__Pseudoxanthomonas sp017302035 | D16: Pseudomonadota | E16: Gammaproteobacteria | F16: Xanthomonadales | G16: Xanthomonadaceae | H16: Pseudoxanthomonas | I16: Pseudoxanthomonas sp017302035 | J16: Pseudoxanthomonas sp017302035 | K16: GCA_017302035.1 | L16: GTDB R220 (GTDB-Tk v2.7.2, classify_wf) | M16: 99.25 | N16: 0.903 | Q16: Same species cluster | R16: Same species-level cluster as closest reference. | T16: GTDB-Tk classification_method: ani_screen. GTDB-Tk note: classification based on ANI only.
A17: CAN_2_bin.173 | B17: Burkholderiaceae.1_m | C17: d__Bacteria;p__Pseudomonadota;c__Gammaproteobacteria;o__Burkholderiales;f__Burkholderiaceae;g__JACDQM01;s__ | D17: Pseudomonadota | E17: Gammaproteobacteria | F17: Burkholderiales | G17: Burkholderiaceae | H17: JACDQM01 | L17: GTDB R220 (GTDB-Tk v2.7.2, classify_wf) | Q17: Unresolved by ANI (GTDB species novel; s__ unassigned) | R17: No close ANI hit and GTDB assigns no species (novel at species level; GTDB-resolved to genus); evaluate exact ANI/AF (skani vs GTDB reps) or AAI/phylogeny. | T17: GTDB-Tk classification_method: taxonomic novelty determined using RED. GTDB-Tk note: classification based on placement in class-level tree.
A18: CAN_2_bin.176 | B18: Thermoanaerobaculia.2_m | C18: d__Bacteria;p__Acidobacteriota;c__Thermoanaerobaculia;o__UBA5066;f__UBA5066;g__UBA5066;s__ | D18: Acidobacteriota | E18: Thermoanaerobaculia | F18: UBA5066 | G18: UBA5066 | H18: UBA5066 | L18: GTDB R220 (GTDB-Tk v2.7.2, classify_wf) | Q18: Unresolved by ANI (GTDB species novel; s__ unassigned) | R18: No close ANI hit and GTDB assigns no species (novel at species level; GTDB-resolved to genus); evaluate exact ANI/AF (skani vs GTDB reps) or AAI/phylogeny. | T18: GTDB-Tk classification_method: taxonomic classification fully defined by topology. GTDB-Tk note: classification based on placement in class-level tree.
A19: CAN_2_bin.23 | B19: Zoogloea.11 | C19: d__Bacteria;p__Pseudomonadota;c__Gammaproteobacteria;o__Burkholderiales;f__Rhodocyclaceae;g__Zoogloea;s__Zoogloea sp023150065 | D19: Pseudomonadota | E19: Gammaproteobacteria | F19: Burkholderiales | G19: Rhodocyclaceae | H19: Zoogloea | I19: Zoogloea sp023150065 | J19: Zoogloea sp023150065 | K19: GCF_023150065.1 | L19: GTDB R220 (GTDB-Tk v2.7.2, classify_wf) | M19: 95.64 | N19: 0.831 | Q19: Same species cluster | R19: Same species-level cluster as closest reference. | T19: GTDB-Tk classification_method: ani_screen. GTDB-Tk note: classification based on ANI only.
A20: CAN_2_bin.6 | B20: Desulfobacillus.1_m | C20: d__Bacteria;p__Pseudomonadota;c__Gammaproteobacteria;o__Burkholderiales;f__Rhodocyclaceae;g__Desulfobacillus;s__ | D20: Pseudomonadota | E20: Gammaproteobacteria | F20: Burkholderiales | G20: Rhodocyclaceae | H20: Desulfobacillus | L20: GTDB R220 (GTDB-Tk v2.7.2, classify_wf) | Q20: Unresolved by ANI (GTDB species novel; s__ unassigned) | R20: No close ANI hit and GTDB assigns no species (novel at species level; GTDB-resolved to genus); evaluate exact ANI/AF (skani vs GTDB reps) or AAI/phylogeny. | T20: GTDB-Tk classification_method: taxonomic classification fully defined by topology. GTDB-Tk note: classification based on placement in class-level tree.
A21: CAN_2_bin.66 | B21: Chthoniobacterales.1_m | C21: d__Bacteria;p__Verrucomicrobiota;c__Verrucomicrobiae;o__Chthoniobacterales;f__JACTMZ01;g__JACTMZ01;s__ | D21: Verrucomicrobiota | E21: Verrucomicrobiae | F21: Chthoniobacterales | G21: JACTMZ01 | H21: JACTMZ01 | L21: GTDB R220 (GTDB-Tk v2.7.2, classify_wf) | Q21: Unresolved by ANI (GTDB species novel; s__ unassigned) | R21: No close ANI hit and GTDB assigns no species (novel at species level; GTDB-resolved to genus); evaluate exact ANI/AF (skani vs GTDB reps) or AAI/phylogeny. | T21: GTDB-Tk classification_method: taxonomic classification fully defined by topology. GTDB-Tk note: classification based on placement in class-level tree.
A22: CAN_3_bin.10 | B22: Rhodobacter.13 | C22: d__Bacteria;p__Pseudomonadota;c__Alphaproteobacteria;o__Rhodobacterales;f__Rhodobacteraceae;g__JAAKGP01;s__ | D22: Pseudomonadota | E22: Alphaproteobacteria | F22: Rhodobacterales | G22: Rhodobacteraceae | H22: JAAKGP01 | L22: GTDB R220 (GTDB-Tk v2.7.2, classify_wf) | Q22: Unresolved by ANI (GTDB species novel; s__ unassigned) | R22: No close ANI hit and GTDB assigns no species (novel at species level; GTDB-resolved to genus); evaluate exact ANI/AF (skani vs GTDB reps) or AAI/phylogeny. | T22: GTDB-Tk classification_method: taxonomic classification fully defined by topology. GTDB-Tk note: classification based on placement in class-level tree.
